5:return {{["x"] = 1, ["y"] = 2, ["z"] = 1, ["name"] = "default:dirt"}, {["x"] = 1, ["y"] = 2, ["z"] = 2, ["name"] = "default:dirt"}, {["x"] = 1, ["y"] = 2, ["z"] = 3, ["name"] = "default:dirt"}, {["x"] = 1, ["y"] = 2, ["z"] = 4, ["name"] = "default:dirt"}, {["x"] = 1, ["y"] = 2, ["z"] = 5, ["name"] = "default:dirt"}, {["x"] = 1, ["y"] = 2, ["z"] = 6, ["name"] = "default:dirt"}, {["x"] = 1, ["y"] = 2, ["z"] = 7, ["name"] = "default:dirt"}, {["x"] = 1, ["y"] = 2, ["z"] = 8, ["name"] = "default:dirt"}, {["x"] = 1, ["y"] = 2, ["z"] = 9, ["name"] = "default:dirt"}, {["x"] = 1, ["y"] = 2, ["z"] = 10, ["name"] = "default:dirt"}, {["x"] = 1, ["y"] = 2, ["z"] = 11, ["name"] = "default:dirt"}, {["x"] = 1, ["y"] = 2, ["z"] = 12, ["name"] = "default:dirt"}, {["x"] = 1, ["y"] = 2, ["z"] = 13, ["name"] = "default:dirt"}, {["x"] = 1, ["y"] = 2, ["z"] = 14, ["name"] = "default:dirt"}, {["x"] = 1, ["y"] = 2, ["z"] = 15, ["name"] = "default:dirt"}, {["x"] = 1, ["y"] = 2, ["z"] = 16, ["name"] = "default:dirt"}, {["x"] = 1, ["y"] = 2, ["z"] = 17, ["name"] = "default:dirt"}, {["x"] = 1, ["y"] = 2, ["z"] = 18, ["name"] = "default:dirt"}, {["x"] = 1, ["y"] = 2, ["z"] = 19, ["name"] = "default:dirt"}, {["x"] = 1, ["y"] = 2, ["z"] = 20, ["name"] = "default:dirt"}, {["x"] = 1, ["y"] = 2, ["z"] = 21, ["name"] = "default:dirt"}, {["x"] = 1, ["y"] = 2, ["z"] = 22, ["name"] = "default:dirt"}, {["x"] = 1, ["y"] = 2, ["z"] = 23, ["name"] = "default:dirt"}, {["x"] = 1, ["y"] = 2, ["z"] = 24, ["name"] = "default:dirt"}, {["x"] = 1, ["y"] = 2, ["z"] = 25, ["name"] = "default:dirt"}, {["x"] = 1, ["y"] = 2, ["z"] = 26, ["name"] = "default:dirt"}, {["x"] = 1, ["y"] = 2, ["z"] = 27, ["name"] = "default:dirt"}, {["x"] = 1, ["y"] = 2, ["z"] = 28, ["name"] = "default:dirt"}, {["x"] = 1, ["y"] = 2, ["z"] = 29, ["name"] = "default:dirt"}, {["x"] = 1, ["y"] = 2, ["z"] = 30, ["name"] = "default:dirt"}, {["x"] = 1, ["y"] = 2, ["z"] = 31, ["name"] = "default:dirt"}, {["x"] = 1, ["y"] = 2, ["z"] = 32, ["name"] = "default:dirt"}, {["x"] = 1, ["y"] = 2, ["z"] = 33, ["name"] = "default:dirt"}, {["x"] = 1, ["y"] = 2, ["z"] = 34, ["name"] = "default:dirt"}, {["x"] = 1, ["y"] = 2, ["z"] = 35, ["name"] = "default:dirt"}, {["x"] = 1, ["y"] = 3, ["param1"] = 15, ["z"] = 1, ["name"] = "default:stonebrick"}, {["x"] = 1, ["y"] = 3, ["param1"] = 15, ["z"] = 2, ["name"] = "default:stonebrick"}, {["x"] = 1, ["y"] = 3, ["param1"] = 15, ["z"] = 3, ["name"] = "default:stonebrick"}, {["x"] = 1, ["y"] = 3, ["z"] = 4, ["name"] = "default:stonebrick"}, {["x"] = 1, ["y"] = 3, ["param1"] = 15, ["z"] = 5, ["name"] = "default:stonebrick"}, {["x"] = 1, ["y"] = 3, ["param1"] = 15, ["z"] = 6, ["name"] = "default:stonebrick"}, {["x"] = 1, ["y"] = 3, ["param1"] = 15, ["z"] = 7, ["name"] = "default:stonebrick"}, {["x"] = 1, ["y"] = 3, ["param1"] = 14, ["z"] = 8, ["name"] = "default:stonebrick"}, {["x"] = 1, ["y"] = 3, ["param1"] = 14, ["z"] = 9, ["name"] = "default:stonebrick"}, {["x"] = 1, ["y"] = 3, ["param1"] = 15, ["z"] = 10, ["name"] = "default:stonebrick"}, {["x"] = 1, ["y"] = 3, ["param1"] = 15, ["z"] = 11, ["name"] = "default:stonebrick"}, {["x"] = 1, ["y"] = 3, ["param1"] = 15, ["z"] = 12, ["name"] = "default:stonebrick"}, {["x"] = 1, ["y"] = 3, ["param1"] = 15, ["z"] = 13, ["name"] = "default:stonebrick"}, {["x"] = 1, ["y"] = 3, ["param1"] = 15, ["z"] = 14, ["name"] = "default:stonebrick"}, {["x"] = 1, ["y"] = 3, ["param1"] = 15, ["z"] = 15, ["name"] = "default:stonebrick"}, {["x"] = 1, ["y"] = 3, ["param1"] = 15, ["z"] = 16, ["name"] = "default:stonebrick"}, {["x"] = 1, ["y"] = 3, ["param1"] = 15, ["z"] = 17, ["name"] = "default:stonebrick"}, {["x"] = 1, ["y"] = 3, ["param1"] = 15, ["z"] = 18, ["name"] = "default:stonebrick"}, {["x"] = 1, ["y"] = 3, ["param1"] = 15, ["z"] = 19, ["name"] = "default:stonebrick"}, {["x"] = 1, ["y"] = 3, ["param1"] = 15, ["z"] = 20, ["name"] = "default:stonebrick"}, {["x"] = 1, ["y"] = 3, ["param1"] = 15, ["z"] = 21, ["name"] = "default:stonebrick"}, {["x"] = 1, ["y"] = 3, ["param1"] = 15, ["z"] = 22, ["name"] = "default:stonebrick"}, {["x"] = 1, ["y"] = 3, ["param1"] = 15, ["z"] = 23, ["name"] = "default:stonebrick"}, {["x"] = 1, ["y"] = 3, ["param1"] = 14, ["z"] = 24, ["name"] = "default:stonebrick"}, {["x"] = 1, ["y"] = 3, ["param1"] = 14, ["z"] = 25, ["name"] = "default:stonebrick"}, {["x"] = 1, ["y"] = 3, ["param1"] = 15, ["z"] = 26, ["name"] = "default:stonebrick"}, {["x"] = 1, ["y"] = 3, ["param1"] = 15, ["z"] = 27, ["name"] = "default:stonebrick"}, {["x"] = 1, ["y"] = 3, ["param1"] = 15, ["z"] = 28, ["name"] = "default:stonebrick"}, {["x"] = 1, ["y"] = 3, ["param1"] = 15, ["z"] = 29, ["name"] = "default:stonebrick"}, {["x"] = 1, ["y"] = 3, ["param1"] = 15, ["z"] = 30, ["name"] = "default:stonebrick"}, {["x"] = 1, ["y"] = 3, ["param1"] = 15, ["z"] = 31, ["name"] = "default:stonebrick"}, {["x"] = 1, ["y"] = 3, ["z"] = 32, ["name"] = "default:stonebrick"}, {["x"] = 1, ["y"] = 3, ["z"] = 33, ["name"] = "default:stonebrick"}, {["x"] = 1, ["y"] = 3, ["z"] = 34, ["name"] = "default:stonebrick"}, {["x"] = 1, ["y"] = 3, ["param1"] = 15, ["z"] = 35, ["name"] = "default:stonebrick"}, {["x"] = 1, ["y"] = 4, ["param1"] = 15, ["z"] = 1, ["name"] = "default:stonebrick"}, {["x"] = 1, ["y"] = 4, ["param1"] = 15, ["z"] = 2, ["name"] = "default:stonebrick"}, {["x"] = 1, ["y"] = 4, ["param1"] = 15, ["z"] = 3, ["name"] = "default:stonebrick"}, {["x"] = 1, ["y"] = 4, ["z"] = 4, ["name"] = "default:stonebrick"}, {["x"] = 1, ["y"] = 4, ["param1"] = 15, ["z"] = 5, ["name"] = "default:stonebrick"}, {["x"] = 1, ["y"] = 4, ["param1"] = 15, ["z"] = 6, ["name"] = "default:stonebrick"}, {["x"] = 1, ["y"] = 4, ["param1"] = 15, ["z"] = 7, ["name"] = "default:stonebrick"}, {["x"] = 1, ["y"] = 4, ["param1"] = 14, ["z"] = 8, ["name"] = "default:stonebrick"}, {["x"] = 1, ["y"] = 4, ["param1"] = 14, ["z"] = 9, ["name"] = "default:stonebrick"}, {["x"] = 1, ["y"] = 4, ["param1"] = 15, ["z"] = 10, ["name"] = "default:stonebrick"}, {["x"] = 1, ["y"] = 4, ["param1"] = 15, ["z"] = 11, ["name"] = "default:stonebrick"}, {["x"] = 1, ["y"] = 4, ["param1"] = 15, ["z"] = 12, ["name"] = "default:stonebrick"}, {["x"] = 1, ["y"] = 4, ["param1"] = 15, ["z"] = 13, ["name"] = "default:stonebrick"}, {["x"] = 1, ["y"] = 4, ["param1"] = 15, ["z"] = 14, ["name"] = "default:stonebrick"}, {["x"] = 1, ["y"] = 4, ["param1"] = 15, ["z"] = 15, ["name"] = "default:stonebrick"}, {["x"] = 1, ["y"] = 4, ["param1"] = 15, ["z"] = 16, ["name"] = "default:stonebrick"}, {["x"] = 1, ["y"] = 4, ["param1"] = 15, ["z"] = 17, ["name"] = "default:stonebrick"}, {["x"] = 1, ["y"] = 4, ["param1"] = 15, ["z"] = 18, ["name"] = "default:stonebrick"}, {["x"] = 1, ["y"] = 4, ["param1"] = 15, ["z"] = 19, ["name"] = "default:stonebrick"}, {["x"] = 1, ["y"] = 4, ["param1"] = 15, ["z"] = 20, ["name"] = "default:stonebrick"}, {["x"] = 1, ["y"] = 4, ["param1"] = 15, ["z"] = 21, ["name"] = "default:stonebrick"}, {["x"] = 1, ["y"] = 4, ["param1"] = 15, ["z"] = 22, ["name"] = "default:stonebrick"}, {["x"] = 1, ["y"] = 4, ["param1"] = 15, ["z"] = 23, ["name"] = "default:stonebrick"}, {["x"] = 1, ["y"] = 4, ["param1"] = 14, ["z"] = 24, ["name"] = "default:stonebrick"}, {["x"] = 1, ["y"] = 4, ["param1"] = 14, ["z"] = 25, ["name"] = "default:stonebrick"}, {["x"] = 1, ["y"] = 4, ["param1"] = 15, ["z"] = 26, ["name"] = "default:stonebrick"}, {["x"] = 1, ["y"] = 4, ["param1"] = 15, ["z"] = 27, ["name"] = "default:stonebrick"}, {["x"] = 1, ["y"] = 4, ["param1"] = 15, ["z"] = 28, ["name"] = "default:stonebrick"}, {["x"] = 1, ["y"] = 4, ["param1"] = 15, ["z"] = 29, ["name"] = "default:stonebrick"}, {["x"] = 1, ["y"] = 4, ["param1"] = 15, ["z"] = 30, ["name"] = "default:stonebrick"}, {["x"] = 1, ["y"] = 4, ["param1"] = 15, ["z"] = 31, ["name"] = "default:stonebrick"}, {["x"] = 1, ["y"] = 4, ["param1"] = 15, ["z"] = 32, ["name"] = "default:stonebrick"}, {["x"] = 1, ["y"] = 4, ["param1"] = 15, ["z"] = 33, ["name"] = "default:stonebrick"}, {["x"] = 1, ["y"] = 4, ["param1"] = 15, ["z"] = 34, ["name"] = "default:stonebrick"}, {["x"] = 1, ["y"] = 4, ["param1"] = 15, ["z"] = 35, ["name"] = "default:stonebrick"}, {["x"] = 1, ["y"] = 5, ["param1"] = 15, ["z"] = 1, ["name"] = "default:stonebrick"}, {["x"] = 1, ["y"] = 5, ["param1"] = 15, ["z"] = 2, ["name"] = "default:stonebrick"}, {["x"] = 1, ["y"] = 5, ["param1"] = 15, ["z"] = 3, ["name"] = "default:stonebrick"}, {["x"] = 1, ["y"] = 5, ["z"] = 4, ["name"] = "default:stonebrick"}, {["x"] = 1, ["y"] = 5, ["param1"] = 15, ["z"] = 5, ["name"] = "default:stonebrick"}, {["x"] = 1, ["y"] = 5, ["param1"] = 15, ["z"] = 6, ["name"] = "default:stonebrick"}, {["x"] = 1, ["y"] = 5, ["param1"] = 15, ["z"] = 7, ["name"] = "default:stonebrick"}, {["x"] = 1, ["y"] = 5, ["param1"] = 14, ["z"] = 8, ["name"] = "default:stonebrick"}, {["x"] = 1, ["y"] = 5, ["param1"] = 14, ["z"] = 9, ["name"] = "default:stonebrick"}, {["x"] = 1, ["y"] = 5, ["param1"] = 15, ["z"] = 10, ["name"] = "default:stonebrick"}, {["x"] = 1, ["y"] = 5, ["param1"] = 15, ["z"] = 11, ["name"] = "default:stonebrick"}, {["x"] = 1, ["y"] = 5, ["param1"] = 15, ["z"] = 12, ["name"] = "default:stonebrick"}, {["x"] = 1, ["y"] = 5, ["param1"] = 15, ["z"] = 13, ["name"] = "default:stonebrick"}, {["x"] = 1, ["y"] = 5, ["param1"] = 15, ["z"] = 14, ["name"] = "default:stonebrick"}, {["x"] = 1, ["y"] = 5, ["param1"] = 15, ["z"] = 15, ["name"] = "default:stonebrick"}, {["x"] = 1, ["y"] = 5, ["param1"] = 15, ["z"] = 16, ["name"] = "default:stonebrick"}, {["x"] = 1, ["y"] = 5, ["param1"] = 15, ["z"] = 17, ["name"] = "default:stonebrick"}, {["x"] = 1, ["y"] = 5, ["param1"] = 15, ["z"] = 18, ["name"] = "default:stonebrick"}, {["x"] = 1, ["y"] = 5, ["param1"] = 15, ["z"] = 19, ["name"] = "default:stonebrick"}, {["x"] = 1, ["y"] = 5, ["param1"] = 15, ["z"] = 20, ["name"] = "default:stonebrick"}, {["x"] = 1, ["y"] = 5, ["param1"] = 15, ["z"] = 21, ["name"] = "default:stonebrick"}, {["x"] = 1, ["y"] = 5, ["param1"] = 15, ["z"] = 22, ["name"] = "default:stonebrick"}, {["x"] = 1, ["y"] = 5, ["param1"] = 15, ["z"] = 23, ["name"] = "default:stonebrick"}, {["x"] = 1, ["y"] = 5, ["param1"] = 14, ["z"] = 24, ["name"] = "default:stonebrick"}, {["x"] = 1, ["y"] = 5, ["param1"] = 14, ["z"] = 25, ["name"] = "default:stonebrick"}, {["x"] = 1, ["y"] = 5, ["param1"] = 15, ["z"] = 26, ["name"] = "default:stonebrick"}, {["x"] = 1, ["y"] = 5, ["param1"] = 15, ["z"] = 27, ["name"] = "default:stonebrick"}, {["x"] = 1, ["y"] = 5, ["param1"] = 15, ["z"] = 28, ["name"] = "default:stonebrick"}, {["x"] = 1, ["y"] = 5, ["param1"] = 15, ["z"] = 29, ["name"] = "default:stonebrick"}, {["x"] = 1, ["y"] = 5, ["param1"] = 15, ["z"] = 30, ["name"] = "default:stonebrick"}, {["x"] = 1, ["y"] = 5, ["param1"] = 15, ["z"] = 31, ["name"] = "default:stonebrick"}, {["x"] = 1, ["y"] = 5, ["param1"] = 15, ["z"] = 32, ["name"] = "default:stonebrick"}, {["x"] = 1, ["y"] = 5, ["param1"] = 15, ["z"] = 33, ["name"] = "default:stonebrick"}, {["x"] = 1, ["y"] = 5, ["param1"] = 15, ["z"] = 34, ["name"] = "default:stonebrick"}, {["x"] = 1, ["y"] = 5, ["param1"] = 15, ["z"] = 35, ["name"] = "default:stonebrick"}, {["x"] = 1, ["y"] = 6, ["param1"] = 15, ["z"] = 1, ["name"] = "default:stonebrick"}, {["x"] = 1, ["y"] = 6, ["param1"] = 15, ["z"] = 2, ["name"] = "default:stonebrick"}, {["x"] = 1, ["y"] = 6, ["param1"] = 15, ["z"] = 3, ["name"] = "default:stonebrick"}, {["x"] = 1, ["y"] = 6, ["z"] = 4, ["name"] = "default:stonebrick"}, {["x"] = 1, ["y"] = 6, ["param1"] = 15, ["z"] = 5, ["name"] = "default:stonebrick"}, {["x"] = 1, ["y"] = 6, ["param1"] = 15, ["z"] = 6, ["name"] = "default:stonebrick"}, {["x"] = 1, ["y"] = 6, ["param1"] = 15, ["z"] = 7, ["name"] = "default:stonebrick"}, {["x"] = 1, ["y"] = 6, ["param1"] = 14, ["z"] = 8, ["name"] = "default:stonebrick"}, {["x"] = 1, ["y"] = 6, ["param1"] = 14, ["z"] = 9, ["name"] = "default:stonebrick"}, {["x"] = 1, ["y"] = 6, ["param1"] = 15, ["z"] = 10, ["name"] = "default:stonebrick"}, {["x"] = 1, ["y"] = 6, ["param1"] = 15, ["z"] = 11, ["name"] = "default:stonebrick"}, {["x"] = 1, ["y"] = 6, ["param1"] = 15, ["z"] = 12, ["name"] = "default:stonebrick"}, {["x"] = 1, ["y"] = 6, ["param1"] = 15, ["z"] = 13, ["name"] = "default:stonebrick"}, {["x"] = 1, ["y"] = 6, ["param1"] = 15, ["z"] = 14, ["name"] = "default:stonebrick"}, {["x"] = 1, ["y"] = 6, ["param1"] = 15, ["z"] = 15, ["name"] = "default:stonebrick"}, {["x"] = 1, ["y"] = 6, ["param1"] = 15, ["z"] = 16, ["name"] = "default:stonebrick"}, {["x"] = 1, ["y"] = 6, ["param1"] = 15, ["z"] = 17, ["name"] = "default:stonebrick"}, {["x"] = 1, ["y"] = 6, ["param1"] = 15, ["z"] = 18, ["name"] = "default:stonebrick"}, {["x"] = 1, ["y"] = 6, ["param1"] = 15, ["z"] = 19, ["name"] = "default:stonebrick"}, {["x"] = 1, ["y"] = 6, ["param1"] = 15, ["z"] = 20, ["name"] = "default:stonebrick"}, {["x"] = 1, ["y"] = 6, ["param1"] = 15, ["z"] = 21, ["name"] = "default:stonebrick"}, {["x"] = 1, ["y"] = 6, ["param1"] = 15, ["z"] = 22, ["name"] = "default:stonebrick"}, {["x"] = 1, ["y"] = 6, ["param1"] = 15, ["z"] = 23, ["name"] = "default:stonebrick"}, {["x"] = 1, ["y"] = 6, ["param1"] = 14, ["z"] = 24, ["name"] = "default:stonebrick"}, {["x"] = 1, ["y"] = 6, ["param1"] = 14, ["z"] = 25, ["name"] = "default:stonebrick"}, {["x"] = 1, ["y"] = 6, ["param1"] = 15, ["z"] = 26, ["name"] = "default:stonebrick"}, {["x"] = 1, ["y"] = 6, ["param1"] = 15, ["z"] = 27, ["name"] = "default:stonebrick"}, {["x"] = 1, ["y"] = 6, ["param1"] = 15, ["z"] = 28, ["name"] = "default:stonebrick"}, {["x"] = 1, ["y"] = 6, ["param1"] = 15, ["z"] = 29, ["name"] = "default:stonebrick"}, {["x"] = 1, ["y"] = 6, ["param1"] = 15, ["z"] = 30, ["name"] = "default:stonebrick"}, {["x"] = 1, ["y"] = 6, ["param1"] = 15, ["z"] = 31, ["name"] = "default:stonebrick"}, {["x"] = 1, ["y"] = 6, ["param1"] = 15, ["z"] = 32, ["name"] = "default:stonebrick"}, {["x"] = 1, ["y"] = 6, ["param1"] = 15, ["z"] = 33, ["name"] = "default:stonebrick"}, {["x"] = 1, ["y"] = 6, ["param1"] = 15, ["z"] = 34, ["name"] = "default:stonebrick"}, {["x"] = 1, ["y"] = 6, ["param1"] = 15, ["z"] = 35, ["name"] = "default:stonebrick"}, {["x"] = 1, ["y"] = 7, ["param1"] = 15, ["z"] = 1, ["name"] = "default:stonebrick"}, {["x"] = 1, ["y"] = 7, ["param1"] = 15, ["z"] = 2, ["name"] = "default:stonebrick"}, {["x"] = 1, ["y"] = 7, ["param1"] = 15, ["z"] = 3, ["name"] = "default:stonebrick"}, {["x"] = 1, ["y"] = 7, ["z"] = 4, ["name"] = "default:stonebrick"}, {["x"] = 1, ["y"] = 7, ["param1"] = 15, ["z"] = 5, ["name"] = "default:stonebrick"}, {["x"] = 1, ["y"] = 7, ["param1"] = 15, ["z"] = 6, ["name"] = "default:stonebrick"}, {["x"] = 1, ["y"] = 7, ["param1"] = 15, ["z"] = 7, ["name"] = "default:stonebrick"}, {["x"] = 1, ["y"] = 7, ["param1"] = 14, ["z"] = 8, ["name"] = "default:stonebrick"}, {["x"] = 1, ["y"] = 7, ["param1"] = 14, ["z"] = 9, ["name"] = "default:stonebrick"}, {["x"] = 1, ["y"] = 7, ["param1"] = 15, ["z"] = 10, ["name"] = "default:stonebrick"}, {["x"] = 1, ["y"] = 7, ["param1"] = 15, ["z"] = 11, ["name"] = "default:stonebrick"}, {["x"] = 1, ["y"] = 7, ["param1"] = 15, ["z"] = 12, ["name"] = "default:stonebrick"}, {["x"] = 1, ["y"] = 7, ["param1"] = 15, ["z"] = 13, ["name"] = "default:stonebrick"}, {["x"] = 1, ["y"] = 7, ["param1"] = 15, ["z"] = 14, ["name"] = "default:stonebrick"}, {["x"] = 1, ["y"] = 7, ["param1"] = 15, ["z"] = 15, ["name"] = "default:stonebrick"}, {["x"] = 1, ["y"] = 7, ["param1"] = 15, ["z"] = 16, ["name"] = "default:stonebrick"}, {["x"] = 1, ["y"] = 7, ["param1"] = 15, ["z"] = 17, ["name"] = "default:stonebrick"}, {["x"] = 1, ["y"] = 7, ["param1"] = 15, ["z"] = 18, ["name"] = "default:stonebrick"}, {["x"] = 1, ["y"] = 7, ["param1"] = 15, ["z"] = 19, ["name"] = "default:stonebrick"}, {["x"] = 1, ["y"] = 7, ["param1"] = 15, ["z"] = 20, ["name"] = "default:stonebrick"}, {["x"] = 1, ["y"] = 7, ["param1"] = 15, ["z"] = 21, ["name"] = "default:stonebrick"}, {["x"] = 1, ["y"] = 7, ["param1"] = 15, ["z"] = 22, ["name"] = "default:stonebrick"}, {["x"] = 1, ["y"] = 7, ["param1"] = 15, ["z"] = 23, ["name"] = "default:stonebrick"}, {["x"] = 1, ["y"] = 7, ["param1"] = 14, ["z"] = 24, ["name"] = "default:stonebrick"}, {["x"] = 1, ["y"] = 7, ["param1"] = 14, ["z"] = 25, ["name"] = "default:stonebrick"}, {["x"] = 1, ["y"] = 7, ["param1"] = 15, ["z"] = 26, ["name"] = "default:stonebrick"}, {["x"] = 1, ["y"] = 7, ["param1"] = 15, ["z"] = 27, ["name"] = "default:stonebrick"}, {["x"] = 1, ["y"] = 7, ["param1"] = 15, ["z"] = 28, ["name"] = "default:stonebrick"}, {["x"] = 1, ["y"] = 7, ["param1"] = 15, ["z"] = 29, ["name"] = "default:stonebrick"}, {["x"] = 1, ["y"] = 7, ["param1"] = 15, ["z"] = 30, ["name"] = "default:stonebrick"}, {["x"] = 1, ["y"] = 7, ["param1"] = 15, ["z"] = 31, ["name"] = "default:stonebrick"}, {["x"] = 1, ["y"] = 7, ["param1"] = 15, ["z"] = 32, ["name"] = "default:stonebrick"}, {["x"] = 1, ["y"] = 7, ["param1"] = 15, ["z"] = 33, ["name"] = "default:stonebrick"}, {["x"] = 1, ["y"] = 7, ["param1"] = 15, ["z"] = 34, ["name"] = "default:stonebrick"}, {["x"] = 1, ["y"] = 7, ["param1"] = 15, ["z"] = 35, ["name"] = "default:stonebrick"}, {["x"] = 2, ["y"] = 2, ["z"] = 1, ["name"] = "default:dirt"}, {["x"] = 2, ["y"] = 2, ["param1"] = 15, ["z"] = 2, ["name"] = "default:dirt"}, {["x"] = 2, ["y"] = 2, ["param1"] = 15, ["z"] = 3, ["name"] = "default:dirt"}, {["x"] = 2, ["y"] = 2, ["param1"] = 15, ["z"] = 4, ["name"] = "default:dirt"}, {["x"] = 2, ["y"] = 2, ["param1"] = 15, ["z"] = 5, ["name"] = "default:dirt"}, {["x"] = 2, ["y"] = 2, ["param1"] = 15, ["z"] = 6, ["name"] = "default:dirt"}, {["x"] = 2, ["y"] = 2, ["param1"] = 15, ["z"] = 7, ["name"] = "default:dirt"}, {["x"] = 2, ["y"] = 2, ["param1"] = 15, ["z"] = 8, ["name"] = "default:dirt"}, {["x"] = 2, ["y"] = 2, ["param1"] = 15, ["z"] = 9, ["name"] = "default:dirt"}, {["x"] = 2, ["y"] = 2, ["param1"] = 15, ["z"] = 10, ["name"] = "default:dirt"}, {["x"] = 2, ["y"] = 2, ["param1"] = 15, ["z"] = 11, ["name"] = "default:dirt"}, {["x"] = 2, ["y"] = 2, ["param1"] = 15, ["z"] = 12, ["name"] = "default:dirt"}, {["x"] = 2, ["y"] = 2, ["param1"] = 15, ["z"] = 13, ["name"] = "default:dirt"}, {["x"] = 2, ["y"] = 2, ["param1"] = 15, ["z"] = 14, ["name"] = "default:dirt"}, {["x"] = 2, ["y"] = 2, ["param1"] = 15, ["z"] = 15, ["name"] = "default:dirt"}, {["x"] = 2, ["y"] = 2, ["param1"] = 15, ["z"] = 16, ["name"] = "default:dirt"}, {["x"] = 2, ["y"] = 2, ["param1"] = 15, ["z"] = 17, ["name"] = "default:dirt"}, {["x"] = 2, ["y"] = 2, ["param1"] = 15, ["z"] = 18, ["name"] = "default:dirt"}, {["x"] = 2, ["y"] = 2, ["param1"] = 15, ["z"] = 19, ["name"] = "default:dirt"}, {["x"] = 2, ["y"] = 2, ["param1"] = 15, ["z"] = 20, ["name"] = "default:dirt"}, {["x"] = 2, ["y"] = 2, ["param1"] = 15, ["z"] = 21, ["name"] = "default:dirt"}, {["x"] = 2, ["y"] = 2, ["param1"] = 15, ["z"] = 22, ["name"] = "default:dirt"}, {["x"] = 2, ["y"] = 2, ["param1"] = 15, ["z"] = 23, ["name"] = "default:dirt"}, {["x"] = 2, ["y"] = 2, ["param1"] = 15, ["z"] = 24, ["name"] = "default:dirt"}, {["x"] = 2, ["y"] = 2, ["param1"] = 15, ["z"] = 25, ["name"] = "default:dirt"}, {["x"] = 2, ["y"] = 2, ["param1"] = 15, ["z"] = 26, ["name"] = "default:dirt"}, {["x"] = 2, ["y"] = 2, ["param1"] = 15, ["z"] = 27, ["name"] = "default:dirt"}, {["x"] = 2, ["y"] = 2, ["param1"] = 15, ["z"] = 28, ["name"] = "default:dirt"}, {["x"] = 2, ["y"] = 2, ["param1"] = 15, ["z"] = 29, ["name"] = "default:dirt"}, {["x"] = 2, ["y"] = 2, ["param1"] = 15, ["z"] = 30, ["name"] = "default:dirt"}, {["x"] = 2, ["y"] = 2, ["param1"] = 15, ["z"] = 31, ["name"] = "default:dirt"}, {["x"] = 2, ["y"] = 2, ["param1"] = 15, ["z"] = 32, ["name"] = "default:dirt"}, {["x"] = 2, ["y"] = 2, ["param1"] = 15, ["z"] = 33, ["name"] = "default:dirt"}, {["x"] = 2, ["y"] = 2, ["param1"] = 15, ["z"] = 34, ["name"] = "default:dirt"}, {["x"] = 2, ["y"] = 2, ["z"] = 35, ["name"] = "default:dirt"}, {["x"] = 2, ["y"] = 3, ["param1"] = 15, ["z"] = 1, ["name"] = "default:stonebrick"}, {["x"] = 2, ["y"] = 3, ["z"] = 5, ["name"] = "default:stonebrick"}, {["x"] = 2, ["y"] = 3, ["z"] = 8, ["name"] = "default:stonebrick"}, {["x"] = 2, ["y"] = 3, ["z"] = 12, ["name"] = "default:stonebrick"}, {["x"] = 2, ["y"] = 3, ["z"] = 15, ["name"] = "default:stonebrick"}, {["x"] = 2, ["y"] = 3, ["z"] = 19, ["name"] = "default:stonebrick"}, {["x"] = 2, ["y"] = 3, ["z"] = 25, ["name"] = "default:stonebrick"}, {["x"] = 2, ["y"] = 3, ["z"] = 29, ["name"] = "default:stonebrick"}, {["x"] = 2, ["y"] = 3, ["z"] = 31, ["name"] = "default:stonebrick"}, {["x"] = 2, ["y"] = 3, ["param1"] = 15, ["z"] = 35, ["name"] = "default:stonebrick"}, {["x"] = 2, ["y"] = 4, ["param1"] = 15, ["z"] = 1, ["name"] = "default:stonebrick"}, {["x"] = 2, ["y"] = 4, ["z"] = 5, ["name"] = "default:stonebrick"}, {["x"] = 2, ["y"] = 4, ["z"] = 8, ["name"] = "default:stonebrick"}, {["x"] = 2, ["y"] = 4, ["z"] = 12, ["name"] = "default:stonebrick"}, {["x"] = 2, ["y"] = 4, ["z"] = 15, ["name"] = "default:stonebrick"}, {["x"] = 2, ["y"] = 4, ["z"] = 19, ["name"] = "default:stonebrick"}, {["x"] = 2, ["y"] = 4, ["z"] = 25, ["name"] = "default:stonebrick"}, {["x"] = 2, ["y"] = 4, ["z"] = 29, ["name"] = "default:stonebrick"}, {["x"] = 2, ["y"] = 4, ["z"] = 31, ["name"] = "default:stonebrick"}, {["x"] = 2, ["y"] = 4, ["param1"] = 15, ["z"] = 35, ["name"] = "default:stonebrick"}, {["x"] = 2, ["y"] = 5, ["param1"] = 15, ["z"] = 1, ["name"] = "default:stonebrick"}, {["x"] = 2, ["y"] = 5, ["z"] = 5, ["name"] = "default:stonebrick"}, {["x"] = 2, ["y"] = 5, ["z"] = 8, ["name"] = "default:stonebrick"}, {["x"] = 2, ["y"] = 5, ["z"] = 12, ["name"] = "default:stonebrick"}, {["x"] = 2, ["y"] = 5, ["z"] = 15, ["name"] = "default:stonebrick"}, {["x"] = 2, ["y"] = 5, ["z"] = 19, ["name"] = "default:stonebrick"}, {["x"] = 2, ["y"] = 5, ["z"] = 25, ["name"] = "default:stonebrick"}, {["x"] = 2, ["y"] = 5, ["z"] = 29, ["name"] = "default:stonebrick"}, {["x"] = 2, ["y"] = 5, ["z"] = 31, ["name"] = "default:stonebrick"}, {["x"] = 2, ["y"] = 5, ["param1"] = 15, ["z"] = 35, ["name"] = "default:stonebrick"}, {["x"] = 2, ["y"] = 6, ["param1"] = 15, ["z"] = 1, ["name"] = "default:stonebrick"}, {["x"] = 2, ["y"] = 6, ["z"] = 5, ["name"] = "default:stonebrick"}, {["x"] = 2, ["y"] = 6, ["z"] = 8, ["name"] = "default:stonebrick"}, {["x"] = 2, ["y"] = 6, ["z"] = 12, ["name"] = "default:stonebrick"}, {["x"] = 2, ["y"] = 6, ["z"] = 15, ["name"] = "default:stonebrick"}, {["x"] = 2, ["y"] = 6, ["z"] = 19, ["name"] = "default:stonebrick"}, {["x"] = 2, ["y"] = 6, ["z"] = 25, ["name"] = "default:stonebrick"}, {["x"] = 2, ["y"] = 6, ["z"] = 29, ["name"] = "default:stonebrick"}, {["x"] = 2, ["y"] = 6, ["z"] = 31, ["name"] = "default:stonebrick"}, {["x"] = 2, ["y"] = 6, ["param1"] = 15, ["z"] = 35, ["name"] = "default:stonebrick"}, {["x"] = 2, ["y"] = 7, ["param1"] = 15, ["z"] = 1, ["name"] = "default:stonebrick"}, {["x"] = 2, ["y"] = 7, ["z"] = 5, ["name"] = "default:stonebrick"}, {["x"] = 2, ["y"] = 7, ["z"] = 8, ["name"] = "default:stonebrick"}, {["x"] = 2, ["y"] = 7, ["z"] = 12, ["name"] = "default:stonebrick"}, {["x"] = 2, ["y"] = 7, ["z"] = 15, ["name"] = "default:stonebrick"}, {["x"] = 2, ["y"] = 7, ["z"] = 19, ["name"] = "default:stonebrick"}, {["x"] = 2, ["y"] = 7, ["z"] = 25, ["name"] = "default:stonebrick"}, {["x"] = 2, ["y"] = 7, ["z"] = 29, ["name"] = "default:stonebrick"}, {["x"] = 2, ["y"] = 7, ["z"] = 31, ["name"] = "default:stonebrick"}, {["x"] = 2, ["y"] = 7, ["param1"] = 15, ["z"] = 35, ["name"] = "default:stonebrick"}, {["x"] = 3, ["y"] = 2, ["z"] = 1, ["name"] = "default:dirt"}, {["x"] = 3, ["y"] = 2, ["param1"] = 15, ["z"] = 2, ["name"] = "default:dirt"}, {["x"] = 3, ["y"] = 2, ["param1"] = 15, ["z"] = 3, ["name"] = "default:dirt"}, {["x"] = 3, ["y"] = 2, ["param1"] = 15, ["z"] = 4, ["name"] = "default:dirt"}, {["x"] = 3, ["y"] = 2, ["param1"] = 15, ["z"] = 5, ["name"] = "default:dirt"}, {["x"] = 3, ["y"] = 2, ["param1"] = 15, ["z"] = 6, ["name"] = "default:dirt"}, {["x"] = 3, ["y"] = 2, ["param1"] = 15, ["z"] = 7, ["name"] = "default:dirt"}, {["x"] = 3, ["y"] = 2, ["param1"] = 15, ["z"] = 8, ["name"] = "default:dirt"}, {["x"] = 3, ["y"] = 2, ["param1"] = 15, ["z"] = 9, ["name"] = "default:dirt"}, {["x"] = 3, ["y"] = 2, ["param1"] = 15, ["z"] = 10, ["name"] = "default:dirt"}, {["x"] = 3, ["y"] = 2, ["param1"] = 15, ["z"] = 11, ["name"] = "default:dirt"}, {["x"] = 3, ["y"] = 2, ["param1"] = 15, ["z"] = 12, ["name"] = "default:dirt"}, {["x"] = 3, ["y"] = 2, ["param1"] = 15, ["z"] = 13, ["name"] = "default:dirt"}, {["x"] = 3, ["y"] = 2, ["param1"] = 15, ["z"] = 14, ["name"] = "default:dirt"}, {["x"] = 3, ["y"] = 2, ["param1"] = 15, ["z"] = 15, ["name"] = "default:dirt"}, {["x"] = 3, ["y"] = 2, ["param1"] = 15, ["z"] = 16, ["name"] = "default:dirt"}, {["x"] = 3, ["y"] = 2, ["param1"] = 15, ["z"] = 17, ["name"] = "default:dirt"}, {["x"] = 3, ["y"] = 2, ["param1"] = 15, ["z"] = 18, ["name"] = "default:dirt"}, {["x"] = 3, ["y"] = 2, ["param1"] = 15, ["z"] = 19, ["name"] = "default:dirt"}, {["x"] = 3, ["y"] = 2, ["param1"] = 15, ["z"] = 20, ["name"] = "default:dirt"}, {["x"] = 3, ["y"] = 2, ["param1"] = 15, ["z"] = 21, ["name"] = "default:dirt"}, {["x"] = 3, ["y"] = 2, ["param1"] = 15, ["z"] = 22, ["name"] = "default:dirt"}, {["x"] = 3, ["y"] = 2, ["param1"] = 15, ["z"] = 23, ["name"] = "default:dirt"}, {["x"] = 3, ["y"] = 2, ["param1"] = 15, ["z"] = 24, ["name"] = "default:dirt"}, {["x"] = 3, ["y"] = 2, ["param1"] = 15, ["z"] = 25, ["name"] = "default:dirt"}, {["x"] = 3, ["y"] = 2, ["param1"] = 15, ["z"] = 26, ["name"] = "default:dirt"}, {["x"] = 3, ["y"] = 2, ["param1"] = 15, ["z"] = 27, ["name"] = "default:dirt"}, {["x"] = 3, ["y"] = 2, ["param1"] = 15, ["z"] = 28, ["name"] = "default:dirt"}, {["x"] = 3, ["y"] = 2, ["param1"] = 15, ["z"] = 29, ["name"] = "default:dirt"}, {["x"] = 3, ["y"] = 2, ["param1"] = 15, ["z"] = 30, ["name"] = "default:dirt"}, {["x"] = 3, ["y"] = 2, ["param1"] = 15, ["z"] = 31, ["name"] = "default:dirt"}, {["x"] = 3, ["y"] = 2, ["param1"] = 15, ["z"] = 32, ["name"] = "default:dirt"}, {["x"] = 3, ["y"] = 2, ["param1"] = 15, ["z"] = 33, ["name"] = "default:dirt"}, {["x"] = 3, ["y"] = 2, ["param1"] = 15, ["z"] = 34, ["name"] = "default:dirt"}, {["x"] = 3, ["y"] = 2, ["z"] = 35, ["name"] = "default:dirt"}, {["x"] = 3, ["y"] = 3, ["param1"] = 15, ["z"] = 1, ["name"] = "default:stonebrick"}, {["x"] = 3, ["y"] = 3, ["z"] = 3, ["name"] = "default:stonebrick"}, {["x"] = 3, ["y"] = 3, ["z"] = 7, ["name"] = "default:stonebrick"}, {["x"] = 3, ["y"] = 3, ["z"] = 8, ["name"] = "default:stonebrick"}, {["x"] = 3, ["y"] = 3, ["z"] = 10, ["name"] = "default:stonebrick"}, {["x"] = 3, ["y"] = 3, ["z"] = 13, ["name"] = "default:stonebrick"}, {["x"] = 3, ["y"] = 3, ["z"] = 17, ["name"] = "default:stonebrick"}, {["x"] = 3, ["y"] = 3, ["z"] = 18, ["name"] = "default:stonebrick"}, {["x"] = 3, ["y"] = 3, ["z"] = 20, ["name"] = "default:stonebrick"}, {["x"] = 3, ["y"] = 3, ["z"] = 22, ["name"] = "default:stonebrick"}, {["x"] = 3, ["y"] = 3, ["z"] = 23, ["name"] = "default:stonebrick"}, {["x"] = 3, ["y"] = 3, ["z"] = 25, ["name"] = "default:stonebrick"}, {["x"] = 3, ["y"] = 3, ["z"] = 27, ["name"] = "default:stonebrick"}, {["x"] = 3, ["y"] = 3, ["z"] = 29, ["name"] = "default:stonebrick"}, {["x"] = 3, ["y"] = 3, ["z"] = 33, ["name"] = "default:stonebrick"}, {["x"] = 3, ["y"] = 3, ["param1"] = 15, ["z"] = 35, ["name"] = "default:stonebrick"}, {["x"] = 3, ["y"] = 4, ["param1"] = 15, ["z"] = 1, ["name"] = "default:stonebrick"}, {["x"] = 3, ["y"] = 4, ["z"] = 3, ["name"] = "default:stonebrick"}, {["x"] = 3, ["y"] = 4, ["z"] = 7, ["name"] = "default:stonebrick"}, {["x"] = 3, ["y"] = 4, ["z"] = 8, ["name"] = "default:stonebrick"}, {["x"] = 3, ["y"] = 4, ["z"] = 10, ["name"] = "default:stonebrick"}, {["x"] = 3, ["y"] = 4, ["z"] = 13, ["name"] = "default:stonebrick"}, {["x"] = 3, ["y"] = 4, ["z"] = 17, ["name"] = "default:stonebrick"}, {["x"] = 3, ["y"] = 4, ["z"] = 18, ["name"] = "default:stonebrick"}, {["x"] = 3, ["y"] = 4, ["z"] = 20, ["name"] = "default:stonebrick"}, {["x"] = 3, ["y"] = 4, ["z"] = 22, ["name"] = "default:stonebrick"}, {["x"] = 3, ["y"] = 4, ["z"] = 23, ["name"] = "default:stonebrick"}, {["x"] = 3, ["y"] = 4, ["z"] = 25, ["name"] = "default:stonebrick"}, {["x"] = 3, ["y"] = 4, ["z"] = 27, ["name"] = "default:stonebrick"}, {["x"] = 3, ["y"] = 4, ["z"] = 29, ["name"] = "default:stonebrick"}, {["x"] = 3, ["y"] = 4, ["z"] = 33, ["name"] = "default:stonebrick"}, {["x"] = 3, ["y"] = 4, ["param1"] = 15, ["z"] = 35, ["name"] = "default:stonebrick"}, {["x"] = 3, ["y"] = 5, ["param1"] = 15, ["z"] = 1, ["name"] = "default:stonebrick"}, {["x"] = 3, ["y"] = 5, ["z"] = 3, ["name"] = "default:stonebrick"}, {["x"] = 3, ["y"] = 5, ["z"] = 7, ["name"] = "default:stonebrick"}, {["x"] = 3, ["y"] = 5, ["z"] = 8, ["name"] = "default:stonebrick"}, {["x"] = 3, ["y"] = 5, ["z"] = 10, ["name"] = "default:stonebrick"}, {["x"] = 3, ["y"] = 5, ["z"] = 13, ["name"] = "default:stonebrick"}, {["x"] = 3, ["y"] = 5, ["z"] = 17, ["name"] = "default:stonebrick"}, {["x"] = 3, ["y"] = 5, ["z"] = 18, ["name"] = "default:stonebrick"}, {["x"] = 3, ["y"] = 5, ["z"] = 20, ["name"] = "default:stonebrick"}, {["x"] = 3, ["y"] = 5, ["z"] = 22, ["name"] = "default:stonebrick"}, {["x"] = 3, ["y"] = 5, ["z"] = 23, ["name"] = "default:stonebrick"}, {["x"] = 3, ["y"] = 5, ["z"] = 25, ["name"] = "default:stonebrick"}, {["x"] = 3, ["y"] = 5, ["z"] = 27, ["name"] = "default:stonebrick"}, {["x"] = 3, ["y"] = 5, ["z"] = 29, ["name"] = "default:stonebrick"}, {["x"] = 3, ["y"] = 5, ["z"] = 33, ["name"] = "default:stonebrick"}, {["x"] = 3, ["y"] = 5, ["param1"] = 15, ["z"] = 35, ["name"] = "default:stonebrick"}, {["x"] = 3, ["y"] = 6, ["param1"] = 15, ["z"] = 1, ["name"] = "default:stonebrick"}, {["x"] = 3, ["y"] = 6, ["z"] = 3, ["name"] = "default:stonebrick"}, {["x"] = 3, ["y"] = 6, ["z"] = 7, ["name"] = "default:stonebrick"}, {["x"] = 3, ["y"] = 6, ["z"] = 8, ["name"] = "default:stonebrick"}, {["x"] = 3, ["y"] = 6, ["z"] = 10, ["name"] = "default:stonebrick"}, {["x"] = 3, ["y"] = 6, ["z"] = 13, ["name"] = "default:stonebrick"}, {["x"] = 3, ["y"] = 6, ["z"] = 17, ["name"] = "default:stonebrick"}, {["x"] = 3, ["y"] = 6, ["z"] = 18, ["name"] = "default:stonebrick"}, {["x"] = 3, ["y"] = 6, ["z"] = 20, ["name"] = "default:stonebrick"}, {["x"] = 3, ["y"] = 6, ["z"] = 22, ["name"] = "default:stonebrick"}, {["x"] = 3, ["y"] = 6, ["z"] = 23, ["name"] = "default:stonebrick"}, {["x"] = 3, ["y"] = 6, ["z"] = 25, ["name"] = "default:stonebrick"}, {["x"] = 3, ["y"] = 6, ["z"] = 27, ["name"] = "default:stonebrick"}, {["x"] = 3, ["y"] = 6, ["z"] = 29, ["name"] = "default:stonebrick"}, {["x"] = 3, ["y"] = 6, ["z"] = 33, ["name"] = "default:stonebrick"}, {["x"] = 3, ["y"] = 6, ["param1"] = 15, ["z"] = 35, ["name"] = "default:stonebrick"}, {["x"] = 3, ["y"] = 7, ["param1"] = 15, ["z"] = 1, ["name"] = "default:stonebrick"}, {["x"] = 3, ["y"] = 7, ["z"] = 3, ["name"] = "default:stonebrick"}, {["x"] = 3, ["y"] = 7, ["z"] = 7, ["name"] = "default:stonebrick"}, {["x"] = 3, ["y"] = 7, ["z"] = 8, ["name"] = "default:stonebrick"}, {["x"] = 3, ["y"] = 7, ["z"] = 10, ["name"] = "default:stonebrick"}, {["x"] = 3, ["y"] = 7, ["z"] = 13, ["name"] = "default:stonebrick"}, {["x"] = 3, ["y"] = 7, ["z"] = 17, ["name"] = "default:stonebrick"}, {["x"] = 3, ["y"] = 7, ["z"] = 18, ["name"] = "default:stonebrick"}, {["x"] = 3, ["y"] = 7, ["z"] = 20, ["name"] = "default:stonebrick"}, {["x"] = 3, ["y"] = 7, ["z"] = 22, ["name"] = "default:stonebrick"}, {["x"] = 3, ["y"] = 7, ["z"] = 23, ["name"] = "default:stonebrick"}, {["x"] = 3, ["y"] = 7, ["z"] = 25, ["name"] = "default:stonebrick"}, {["x"] = 3, ["y"] = 7, ["z"] = 27, ["name"] = "default:stonebrick"}, {["x"] = 3, ["y"] = 7, ["z"] = 29, ["name"] = "default:stonebrick"}, {["x"] = 3, ["y"] = 7, ["z"] = 33, ["name"] = "default:stonebrick"}, {["x"] = 3, ["y"] = 7, ["param1"] = 15, ["z"] = 35, ["name"] = "default:stonebrick"}, {["x"] = 4, ["y"] = 2, ["z"] = 1, ["name"] = "default:dirt"}, {["x"] = 4, ["y"] = 2, ["param1"] = 15, ["z"] = 2, ["name"] = "default:dirt"}, {["x"] = 4, ["y"] = 2, ["param1"] = 15, ["z"] = 3, ["name"] = "default:dirt"}, {["x"] = 4, ["y"] = 2, ["param1"] = 15, ["z"] = 4, ["name"] = "default:dirt"}, {["x"] = 4, ["y"] = 2, ["param1"] = 15, ["z"] = 5, ["name"] = "default:dirt"}, {["x"] = 4, ["y"] = 2, ["param1"] = 15, ["z"] = 6, ["name"] = "default:dirt"}, {["x"] = 4, ["y"] = 2, ["param1"] = 15, ["z"] = 7, ["name"] = "default:dirt"}, {["x"] = 4, ["y"] = 2, ["param1"] = 15, ["z"] = 8, ["name"] = "default:dirt"}, {["x"] = 4, ["y"] = 2, ["param1"] = 15, ["z"] = 9, ["name"] = "default:dirt"}, {["x"] = 4, ["y"] = 2, ["param1"] = 15, ["z"] = 10, ["name"] = "default:dirt"}, {["x"] = 4, ["y"] = 2, ["param1"] = 15, ["z"] = 11, ["name"] = "default:dirt"}, {["x"] = 4, ["y"] = 2, ["param1"] = 15, ["z"] = 12, ["name"] = "default:dirt"}, {["x"] = 4, ["y"] = 2, ["param1"] = 15, ["z"] = 13, ["name"] = "default:dirt"}, {["x"] = 4, ["y"] = 2, ["param1"] = 15, ["z"] = 14, ["name"] = "default:dirt"}, {["x"] = 4, ["y"] = 2, ["param1"] = 15, ["z"] = 15, ["name"] = "default:dirt"}, {["x"] = 4, ["y"] = 2, ["param1"] = 15, ["z"] = 16, ["name"] = "default:dirt"}, {["x"] = 4, ["y"] = 2, ["param1"] = 15, ["z"] = 17, ["name"] = "default:dirt"}, {["x"] = 4, ["y"] = 2, ["param1"] = 15, ["z"] = 18, ["name"] = "default:dirt"}, {["x"] = 4, ["y"] = 2, ["param1"] = 15, ["z"] = 19, ["name"] = "default:dirt"}, {["x"] = 4, ["y"] = 2, ["param1"] = 15, ["z"] = 20, ["name"] = "default:dirt"}, {["x"] = 4, ["y"] = 2, ["param1"] = 15, ["z"] = 21, ["name"] = "default:dirt"}, {["x"] = 4, ["y"] = 2, ["param1"] = 15, ["z"] = 22, ["name"] = "default:dirt"}, {["x"] = 4, ["y"] = 2, ["param1"] = 15, ["z"] = 23, ["name"] = "default:dirt"}, {["x"] = 4, ["y"] = 2, ["param1"] = 15, ["z"] = 24, ["name"] = "default:dirt"}, {["x"] = 4, ["y"] = 2, ["param1"] = 15, ["z"] = 25, ["name"] = "default:dirt"}, {["x"] = 4, ["y"] = 2, ["param1"] = 15, ["z"] = 26, ["name"] = "default:dirt"}, {["x"] = 4, ["y"] = 2, ["param1"] = 15, ["z"] = 27, ["name"] = "default:dirt"}, {["x"] = 4, ["y"] = 2, ["param1"] = 15, ["z"] = 28, ["name"] = "default:dirt"}, {["x"] = 4, ["y"] = 2, ["param1"] = 15, ["z"] = 29, ["name"] = "default:dirt"}, {["x"] = 4, ["y"] = 2, ["param1"] = 15, ["z"] = 30, ["name"] = "default:dirt"}, {["x"] = 4, ["y"] = 2, ["param1"] = 15, ["z"] = 31, ["name"] = "default:dirt"}, {["x"] = 4, ["y"] = 2, ["param1"] = 15, ["z"] = 32, ["name"] = "default:dirt"}, {["x"] = 4, ["y"] = 2, ["param1"] = 15, ["z"] = 33, ["name"] = "default:dirt"}, {["x"] = 4, ["y"] = 2, ["param1"] = 15, ["z"] = 34, ["name"] = "default:dirt"}, {["x"] = 4, ["y"] = 2, ["z"] = 35, ["name"] = "default:dirt"}, {["x"] = 4, ["y"] = 3, ["z"] = 3, ["name"] = "default:stonebrick"}, {["x"] = 4, ["y"] = 3, ["z"] = 4, ["name"] = "default:stonebrick"}, {["x"] = 4, ["y"] = 3, ["z"] = 5, ["name"] = "default:stonebrick"}, {["x"] = 4, ["y"] = 3, ["z"] = 11, ["name"] = "default:stonebrick"}, {["x"] = 4, ["y"] = 3, ["z"] = 14, ["name"] = "default:stonebrick"}, {["x"] = 4, ["y"] = 3, ["z"] = 15, ["name"] = "default:stonebrick"}, {["x"] = 4, ["y"] = 3, ["z"] = 20, ["name"] = "default:stonebrick"}, {["x"] = 4, ["y"] = 3, ["z"] = 22, ["name"] = "default:stonebrick"}, {["x"] = 4, ["y"] = 3, ["z"] = 25, ["name"] = "default:stonebrick"}, {["x"] = 4, ["y"] = 3, ["z"] = 31, ["name"] = "default:stonebrick"}, {["x"] = 4, ["y"] = 3, ["z"] = 32, ["name"] = "default:stonebrick"}, {["x"] = 4, ["y"] = 3, ["z"] = 33, ["name"] = "default:stonebrick"}, {["x"] = 4, ["y"] = 3, ["param1"] = 15, ["z"] = 35, ["name"] = "default:stonebrick"}, {["x"] = 4, ["y"] = 4, ["z"] = 3, ["name"] = "default:stonebrick"}, {["x"] = 4, ["y"] = 4, ["z"] = 4, ["name"] = "default:stonebrick"}, {["x"] = 4, ["y"] = 4, ["z"] = 5, ["name"] = "default:stonebrick"}, {["x"] = 4, ["y"] = 4, ["z"] = 11, ["name"] = "default:stonebrick"}, {["x"] = 4, ["y"] = 4, ["z"] = 14, ["name"] = "default:stonebrick"}, {["x"] = 4, ["y"] = 4, ["z"] = 15, ["name"] = "default:stonebrick"}, {["x"] = 4, ["y"] = 4, ["z"] = 20, ["name"] = "default:stonebrick"}, {["x"] = 4, ["y"] = 4, ["z"] = 22, ["name"] = "default:stonebrick"}, {["x"] = 4, ["y"] = 4, ["z"] = 25, ["name"] = "default:stonebrick"}, {["x"] = 4, ["y"] = 4, ["z"] = 31, ["name"] = "default:stonebrick"}, {["x"] = 4, ["y"] = 4, ["z"] = 32, ["name"] = "default:stonebrick"}, {["x"] = 4, ["y"] = 4, ["z"] = 33, ["name"] = "default:stonebrick"}, {["x"] = 4, ["y"] = 4, ["param1"] = 15, ["z"] = 35, ["name"] = "default:stonebrick"}, {["x"] = 4, ["y"] = 5, ["z"] = 3, ["name"] = "default:stonebrick"}, {["x"] = 4, ["y"] = 5, ["z"] = 4, ["name"] = "default:stonebrick"}, {["x"] = 4, ["y"] = 5, ["z"] = 5, ["name"] = "default:stonebrick"}, {["x"] = 4, ["y"] = 5, ["z"] = 11, ["name"] = "default:stonebrick"}, {["x"] = 4, ["y"] = 5, ["z"] = 14, ["name"] = "default:stonebrick"}, {["x"] = 4, ["y"] = 5, ["z"] = 15, ["name"] = "default:stonebrick"}, {["x"] = 4, ["y"] = 5, ["z"] = 20, ["name"] = "default:stonebrick"}, {["x"] = 4, ["y"] = 5, ["z"] = 22, ["name"] = "default:stonebrick"}, {["x"] = 4, ["y"] = 5, ["z"] = 25, ["name"] = "default:stonebrick"}, {["x"] = 4, ["y"] = 5, ["z"] = 31, ["name"] = "default:stonebrick"}, {["x"] = 4, ["y"] = 5, ["z"] = 32, ["name"] = "default:stonebrick"}, {["x"] = 4, ["y"] = 5, ["z"] = 33, ["name"] = "default:stonebrick"}, {["x"] = 4, ["y"] = 5, ["param1"] = 15, ["z"] = 35, ["name"] = "default:stonebrick"}, {["x"] = 4, ["y"] = 6, ["z"] = 3, ["name"] = "default:stonebrick"}, {["x"] = 4, ["y"] = 6, ["z"] = 4, ["name"] = "default:stonebrick"}, {["x"] = 4, ["y"] = 6, ["z"] = 5, ["name"] = "default:stonebrick"}, {["x"] = 4, ["y"] = 6, ["z"] = 11, ["name"] = "default:stonebrick"}, {["x"] = 4, ["y"] = 6, ["z"] = 14, ["name"] = "default:stonebrick"}, {["x"] = 4, ["y"] = 6, ["z"] = 15, ["name"] = "default:stonebrick"}, {["x"] = 4, ["y"] = 6, ["z"] = 20, ["name"] = "default:stonebrick"}, {["x"] = 4, ["y"] = 6, ["z"] = 22, ["name"] = "default:stonebrick"}, {["x"] = 4, ["y"] = 6, ["z"] = 25, ["name"] = "default:stonebrick"}, {["x"] = 4, ["y"] = 6, ["z"] = 31, ["name"] = "default:stonebrick"}, {["x"] = 4, ["y"] = 6, ["z"] = 32, ["name"] = "default:stonebrick"}, {["x"] = 4, ["y"] = 6, ["z"] = 33, ["name"] = "default:stonebrick"}, {["x"] = 4, ["y"] = 6, ["param1"] = 15, ["z"] = 35, ["name"] = "default:stonebrick"}, {["x"] = 4, ["y"] = 7, ["z"] = 3, ["name"] = "default:stonebrick"}, {["x"] = 4, ["y"] = 7, ["z"] = 4, ["name"] = "default:stonebrick"}, {["x"] = 4, ["y"] = 7, ["z"] = 5, ["name"] = "default:stonebrick"}, {["x"] = 4, ["y"] = 7, ["z"] = 11, ["name"] = "default:stonebrick"}, {["x"] = 4, ["y"] = 7, ["z"] = 14, ["name"] = "default:stonebrick"}, {["x"] = 4, ["y"] = 7, ["z"] = 15, ["name"] = "default:stonebrick"}, {["x"] = 4, ["y"] = 7, ["z"] = 20, ["name"] = "default:stonebrick"}, {["x"] = 4, ["y"] = 7, ["z"] = 22, ["name"] = "default:stonebrick"}, {["x"] = 4, ["y"] = 7, ["z"] = 25, ["name"] = "default:stonebrick"}, {["x"] = 4, ["y"] = 7, ["z"] = 31, ["name"] = "default:stonebrick"}, {["x"] = 4, ["y"] = 7, ["z"] = 32, ["name"] = "default:stonebrick"}, {["x"] = 4, ["y"] = 7, ["z"] = 33, ["name"] = "default:stonebrick"}, {["x"] = 4, ["y"] = 7, ["param1"] = 15, ["z"] = 35, ["name"] = "default:stonebrick"}, {["x"] = 5, ["y"] = 2, ["z"] = 1, ["name"] = "default:dirt"}, {["x"] = 5, ["y"] = 2, ["param1"] = 15, ["z"] = 2, ["name"] = "default:dirt"}, {["x"] = 5, ["y"] = 2, ["param1"] = 15, ["z"] = 3, ["name"] = "default:dirt"}, {["x"] = 5, ["y"] = 2, ["param1"] = 15, ["z"] = 4, ["name"] = "default:dirt"}, {["x"] = 5, ["y"] = 2, ["param1"] = 15, ["z"] = 5, ["name"] = "default:dirt"}, {["x"] = 5, ["y"] = 2, ["param1"] = 15, ["z"] = 6, ["name"] = "default:dirt"}, {["x"] = 5, ["y"] = 2, ["param1"] = 15, ["z"] = 7, ["name"] = "default:dirt"}, {["x"] = 5, ["y"] = 2, ["param1"] = 15, ["z"] = 8, ["name"] = "default:dirt"}, {["x"] = 5, ["y"] = 2, ["param1"] = 15, ["z"] = 9, ["name"] = "default:dirt"}, {["x"] = 5, ["y"] = 2, ["param1"] = 15, ["z"] = 10, ["name"] = "default:dirt"}, {["x"] = 5, ["y"] = 2, ["param1"] = 15, ["z"] = 11, ["name"] = "default:dirt"}, {["x"] = 5, ["y"] = 2, ["param1"] = 15, ["z"] = 12, ["name"] = "default:dirt"}, {["x"] = 5, ["y"] = 2, ["param1"] = 15, ["z"] = 13, ["name"] = "default:dirt"}, {["x"] = 5, ["y"] = 2, ["param1"] = 15, ["z"] = 14, ["name"] = "default:dirt"}, {["x"] = 5, ["y"] = 2, ["param1"] = 15, ["z"] = 15, ["name"] = "default:dirt"}, {["x"] = 5, ["y"] = 2, ["param1"] = 15, ["z"] = 16, ["name"] = "default:dirt"}, {["x"] = 5, ["y"] = 2, ["param1"] = 15, ["z"] = 17, ["name"] = "default:dirt"}, {["x"] = 5, ["y"] = 2, ["param1"] = 15, ["z"] = 18, ["name"] = "default:dirt"}, {["x"] = 5, ["y"] = 2, ["param1"] = 15, ["z"] = 19, ["name"] = "default:dirt"}, {["x"] = 5, ["y"] = 2, ["param1"] = 15, ["z"] = 20, ["name"] = "default:dirt"}, {["x"] = 5, ["y"] = 2, ["param1"] = 15, ["z"] = 21, ["name"] = "default:dirt"}, {["x"] = 5, ["y"] = 2, ["param1"] = 15, ["z"] = 22, ["name"] = "default:dirt"}, {["x"] = 5, ["y"] = 2, ["param1"] = 15, ["z"] = 23, ["name"] = "default:dirt"}, {["x"] = 5, ["y"] = 2, ["param1"] = 15, ["z"] = 24, ["name"] = "default:dirt"}, {["x"] = 5, ["y"] = 2, ["param1"] = 15, ["z"] = 25, ["name"] = "default:dirt"}, {["x"] = 5, ["y"] = 2, ["param1"] = 15, ["z"] = 26, ["name"] = "default:dirt"}, {["x"] = 5, ["y"] = 2, ["param1"] = 15, ["z"] = 27, ["name"] = "default:dirt"}, {["x"] = 5, ["y"] = 2, ["param1"] = 15, ["z"] = 28, ["name"] = "default:dirt"}, {["x"] = 5, ["y"] = 2, ["param1"] = 15, ["z"] = 29, ["name"] = "default:dirt"}, {["x"] = 5, ["y"] = 2, ["param1"] = 15, ["z"] = 30, ["name"] = "default:dirt"}, {["x"] = 5, ["y"] = 2, ["param1"] = 15, ["z"] = 31, ["name"] = "default:dirt"}, {["x"] = 5, ["y"] = 2, ["param1"] = 15, ["z"] = 32, ["name"] = "default:dirt"}, {["x"] = 5, ["y"] = 2, ["param1"] = 15, ["z"] = 33, ["name"] = "default:dirt"}, {["x"] = 5, ["y"] = 2, ["param1"] = 15, ["z"] = 34, ["name"] = "default:dirt"}, {["x"] = 5, ["y"] = 2, ["z"] = 35, ["name"] = "default:dirt"}, {["x"] = 5, ["y"] = 3, ["param1"] = 15, ["z"] = 1, ["name"] = "default:stonebrick"}, {["x"] = 5, ["y"] = 3, ["z"] = 2, ["name"] = "default:stonebrick"}, {["x"] = 5, ["y"] = 3, ["z"] = 6, ["name"] = "default:stonebrick"}, {["x"] = 5, ["y"] = 3, ["z"] = 8, ["name"] = "default:stonebrick"}, {["x"] = 5, ["y"] = 3, ["z"] = 9, ["name"] = "default:stonebrick"}, {["x"] = 5, ["y"] = 3, ["z"] = 12, ["name"] = "default:stonebrick"}, {["x"] = 5, ["y"] = 3, ["z"] = 14, ["name"] = "default:stonebrick"}, {["x"] = 5, ["y"] = 3, ["z"] = 15, ["name"] = "default:stonebrick"}, {["x"] = 5, ["y"] = 3, ["z"] = 16, ["name"] = "default:stonebrick"}, {["x"] = 5, ["y"] = 3, ["z"] = 19, ["name"] = "default:stonebrick"}, {["x"] = 5, ["y"] = 3, ["z"] = 21, ["name"] = "default:stonebrick"}, {["x"] = 5, ["y"] = 3, ["z"] = 22, ["name"] = "default:stonebrick"}, {["x"] = 5, ["y"] = 3, ["z"] = 24, ["name"] = "default:stonebrick"}, {["x"] = 5, ["y"] = 3, ["z"] = 27, ["name"] = "default:stonebrick"}, {["x"] = 5, ["y"] = 3, ["z"] = 28, ["name"] = "default:stonebrick"}, {["x"] = 5, ["y"] = 3, ["z"] = 29, ["name"] = "default:stonebrick"}, {["x"] = 5, ["y"] = 3, ["z"] = 33, ["name"] = "default:stonebrick"}, {["x"] = 5, ["y"] = 3, ["param1"] = 15, ["z"] = 35, ["name"] = "default:stonebrick"}, {["x"] = 5, ["y"] = 4, ["param1"] = 15, ["z"] = 1, ["name"] = "default:stonebrick"}, {["x"] = 5, ["y"] = 4, ["z"] = 2, ["name"] = "default:stonebrick"}, {["x"] = 5, ["y"] = 4, ["z"] = 6, ["name"] = "default:stonebrick"}, {["x"] = 5, ["y"] = 4, ["z"] = 8, ["name"] = "default:stonebrick"}, {["x"] = 5, ["y"] = 4, ["z"] = 9, ["name"] = "default:stonebrick"}, {["x"] = 5, ["y"] = 4, ["z"] = 12, ["name"] = "default:stonebrick"}, {["x"] = 5, ["y"] = 4, ["z"] = 14, ["name"] = "default:stonebrick"}, {["x"] = 5, ["y"] = 4, ["z"] = 15, ["name"] = "default:stonebrick"}, {["x"] = 5, ["y"] = 4, ["z"] = 16, ["name"] = "default:stonebrick"}, {["x"] = 5, ["y"] = 4, ["z"] = 19, ["name"] = "default:stonebrick"}, {["x"] = 5, ["y"] = 4, ["z"] = 21, ["name"] = "default:stonebrick"}, {["x"] = 5, ["y"] = 4, ["z"] = 22, ["name"] = "default:stonebrick"}, {["x"] = 5, ["y"] = 4, ["z"] = 24, ["name"] = "default:stonebrick"}, {["x"] = 5, ["y"] = 4, ["z"] = 27, ["name"] = "default:stonebrick"}, {["x"] = 5, ["y"] = 4, ["z"] = 28, ["name"] = "default:stonebrick"}, {["x"] = 5, ["y"] = 4, ["z"] = 29, ["name"] = "default:stonebrick"}, {["x"] = 5, ["y"] = 4, ["z"] = 33, ["name"] = "default:stonebrick"}, {["x"] = 5, ["y"] = 4, ["param1"] = 15, ["z"] = 35, ["name"] = "default:stonebrick"}, {["x"] = 5, ["y"] = 5, ["param1"] = 15, ["z"] = 1, ["name"] = "default:stonebrick"}, {["x"] = 5, ["y"] = 5, ["z"] = 2, ["name"] = "default:stonebrick"}, {["x"] = 5, ["y"] = 5, ["z"] = 6, ["name"] = "default:stonebrick"}, {["x"] = 5, ["y"] = 5, ["z"] = 8, ["name"] = "default:stonebrick"}, {["x"] = 5, ["y"] = 5, ["z"] = 9, ["name"] = "default:stonebrick"}, {["x"] = 5, ["y"] = 5, ["z"] = 12, ["name"] = "default:stonebrick"}, {["x"] = 5, ["y"] = 5, ["z"] = 14, ["name"] = "default:stonebrick"}, {["x"] = 5, ["y"] = 5, ["z"] = 15, ["name"] = "default:stonebrick"}, {["x"] = 5, ["y"] = 5, ["z"] = 16, ["name"] = "default:stonebrick"}, {["x"] = 5, ["y"] = 5, ["z"] = 19, ["name"] = "default:stonebrick"}, {["x"] = 5, ["y"] = 5, ["z"] = 21, ["name"] = "default:stonebrick"}, {["x"] = 5, ["y"] = 5, ["z"] = 22, ["name"] = "default:stonebrick"}, {["x"] = 5, ["y"] = 5, ["z"] = 24, ["name"] = "default:stonebrick"}, {["x"] = 5, ["y"] = 5, ["z"] = 27, ["name"] = "default:stonebrick"}, {["x"] = 5, ["y"] = 5, ["z"] = 28, ["name"] = "default:stonebrick"}, {["x"] = 5, ["y"] = 5, ["z"] = 29, ["name"] = "default:stonebrick"}, {["x"] = 5, ["y"] = 5, ["z"] = 33, ["name"] = "default:stonebrick"}, {["x"] = 5, ["y"] = 5, ["param1"] = 15, ["z"] = 35, ["name"] = "default:stonebrick"}, {["x"] = 5, ["y"] = 6, ["param1"] = 15, ["z"] = 1, ["name"] = "default:stonebrick"}, {["x"] = 5, ["y"] = 6, ["z"] = 2, ["name"] = "default:stonebrick"}, {["x"] = 5, ["y"] = 6, ["z"] = 6, ["name"] = "default:stonebrick"}, {["x"] = 5, ["y"] = 6, ["z"] = 8, ["name"] = "default:stonebrick"}, {["x"] = 5, ["y"] = 6, ["z"] = 9, ["name"] = "default:stonebrick"}, {["x"] = 5, ["y"] = 6, ["z"] = 12, ["name"] = "default:stonebrick"}, {["x"] = 5, ["y"] = 6, ["z"] = 14, ["name"] = "default:stonebrick"}, {["x"] = 5, ["y"] = 6, ["z"] = 15, ["name"] = "default:stonebrick"}, {["x"] = 5, ["y"] = 6, ["z"] = 16, ["name"] = "default:stonebrick"}, {["x"] = 5, ["y"] = 6, ["z"] = 19, ["name"] = "default:stonebrick"}, {["x"] = 5, ["y"] = 6, ["z"] = 21, ["name"] = "default:stonebrick"}, {["x"] = 5, ["y"] = 6, ["z"] = 22, ["name"] = "default:stonebrick"}, {["x"] = 5, ["y"] = 6, ["z"] = 24, ["name"] = "default:stonebrick"}, {["x"] = 5, ["y"] = 6, ["z"] = 27, ["name"] = "default:stonebrick"}, {["x"] = 5, ["y"] = 6, ["z"] = 28, ["name"] = "default:stonebrick"}, {["x"] = 5, ["y"] = 6, ["z"] = 29, ["name"] = "default:stonebrick"}, {["x"] = 5, ["y"] = 6, ["z"] = 33, ["name"] = "default:stonebrick"}, {["x"] = 5, ["y"] = 6, ["param1"] = 15, ["z"] = 35, ["name"] = "default:stonebrick"}, {["x"] = 5, ["y"] = 7, ["param1"] = 15, ["z"] = 1, ["name"] = "default:stonebrick"}, {["x"] = 5, ["y"] = 7, ["z"] = 2, ["name"] = "default:stonebrick"}, {["x"] = 5, ["y"] = 7, ["z"] = 6, ["name"] = "default:stonebrick"}, {["x"] = 5, ["y"] = 7, ["z"] = 8, ["name"] = "default:stonebrick"}, {["x"] = 5, ["y"] = 7, ["z"] = 9, ["name"] = "default:stonebrick"}, {["x"] = 5, ["y"] = 7, ["z"] = 12, ["name"] = "default:stonebrick"}, {["x"] = 5, ["y"] = 7, ["z"] = 14, ["name"] = "default:stonebrick"}, {["x"] = 5, ["y"] = 7, ["z"] = 15, ["name"] = "default:stonebrick"}, {["x"] = 5, ["y"] = 7, ["z"] = 16, ["name"] = "default:stonebrick"}, {["x"] = 5, ["y"] = 7, ["z"] = 19, ["name"] = "default:stonebrick"}, {["x"] = 5, ["y"] = 7, ["z"] = 21, ["name"] = "default:stonebrick"}, {["x"] = 5, ["y"] = 7, ["z"] = 22, ["name"] = "default:stonebrick"}, {["x"] = 5, ["y"] = 7, ["z"] = 24, ["name"] = "default:stonebrick"}, {["x"] = 5, ["y"] = 7, ["z"] = 27, ["name"] = "default:stonebrick"}, {["x"] = 5, ["y"] = 7, ["z"] = 28, ["name"] = "default:stonebrick"}, {["x"] = 5, ["y"] = 7, ["z"] = 29, ["name"] = "default:stonebrick"}, {["x"] = 5, ["y"] = 7, ["z"] = 33, ["name"] = "default:stonebrick"}, {["x"] = 5, ["y"] = 7, ["param1"] = 15, ["z"] = 35, ["name"] = "default:stonebrick"}, {["x"] = 6, ["y"] = 2, ["z"] = 1, ["name"] = "default:dirt"}, {["x"] = 6, ["y"] = 2, ["param1"] = 15, ["z"] = 2, ["name"] = "default:dirt"}, {["x"] = 6, ["y"] = 2, ["param1"] = 15, ["z"] = 3, ["name"] = "default:dirt"}, {["x"] = 6, ["y"] = 2, ["param1"] = 15, ["z"] = 4, ["name"] = "default:dirt"}, {["x"] = 6, ["y"] = 2, ["param1"] = 15, ["z"] = 5, ["name"] = "default:dirt"}, {["x"] = 6, ["y"] = 2, ["param1"] = 15, ["z"] = 6, ["name"] = "default:dirt"}, {["x"] = 6, ["y"] = 2, ["param1"] = 15, ["z"] = 7, ["name"] = "default:dirt"}, {["x"] = 6, ["y"] = 2, ["param1"] = 15, ["z"] = 8, ["name"] = "default:dirt"}, {["x"] = 6, ["y"] = 2, ["param1"] = 15, ["z"] = 9, ["name"] = "default:dirt"}, {["x"] = 6, ["y"] = 2, ["param1"] = 15, ["z"] = 10, ["name"] = "default:dirt"}, {["x"] = 6, ["y"] = 2, ["param1"] = 15, ["z"] = 11, ["name"] = "default:dirt"}, {["x"] = 6, ["y"] = 2, ["param1"] = 15, ["z"] = 12, ["name"] = "default:dirt"}, {["x"] = 6, ["y"] = 2, ["param1"] = 15, ["z"] = 13, ["name"] = "default:dirt"}, {["x"] = 6, ["y"] = 2, ["param1"] = 15, ["z"] = 14, ["name"] = "default:dirt"}, {["x"] = 6, ["y"] = 2, ["param1"] = 15, ["z"] = 15, ["name"] = "default:dirt"}, {["x"] = 6, ["y"] = 2, ["param1"] = 15, ["z"] = 16, ["name"] = "default:dirt"}, {["x"] = 6, ["y"] = 2, ["param1"] = 15, ["z"] = 17, ["name"] = "default:dirt"}, {["x"] = 6, ["y"] = 2, ["param1"] = 15, ["z"] = 18, ["name"] = "default:dirt"}, {["x"] = 6, ["y"] = 2, ["param1"] = 15, ["z"] = 19, ["name"] = "default:dirt"}, {["x"] = 6, ["y"] = 2, ["param1"] = 15, ["z"] = 20, ["name"] = "default:dirt"}, {["x"] = 6, ["y"] = 2, ["param1"] = 15, ["z"] = 21, ["name"] = "default:dirt"}, {["x"] = 6, ["y"] = 2, ["param1"] = 15, ["z"] = 22, ["name"] = "default:dirt"}, {["x"] = 6, ["y"] = 2, ["param1"] = 15, ["z"] = 23, ["name"] = "default:dirt"}, {["x"] = 6, ["y"] = 2, ["param1"] = 15, ["z"] = 24, ["name"] = "default:dirt"}, {["x"] = 6, ["y"] = 2, ["param1"] = 15, ["z"] = 25, ["name"] = "default:dirt"}, {["x"] = 6, ["y"] = 2, ["param1"] = 15, ["z"] = 26, ["name"] = "default:dirt"}, {["x"] = 6, ["y"] = 2, ["param1"] = 15, ["z"] = 27, ["name"] = "default:dirt"}, {["x"] = 6, ["y"] = 2, ["param1"] = 15, ["z"] = 28, ["name"] = "default:dirt"}, {["x"] = 6, ["y"] = 2, ["param1"] = 15, ["z"] = 29, ["name"] = "default:dirt"}, {["x"] = 6, ["y"] = 2, ["param1"] = 15, ["z"] = 30, ["name"] = "default:dirt"}, {["x"] = 6, ["y"] = 2, ["param1"] = 15, ["z"] = 31, ["name"] = "default:dirt"}, {["x"] = 6, ["y"] = 2, ["param1"] = 15, ["z"] = 32, ["name"] = "default:dirt"}, {["x"] = 6, ["y"] = 2, ["param1"] = 15, ["z"] = 33, ["name"] = "default:dirt"}, {["x"] = 6, ["y"] = 2, ["param1"] = 15, ["z"] = 34, ["name"] = "default:dirt"}, {["x"] = 6, ["y"] = 2, ["z"] = 35, ["name"] = "default:dirt"}, {["x"] = 6, ["y"] = 3, ["param1"] = 15, ["z"] = 1, ["name"] = "default:stonebrick"}, {["x"] = 6, ["y"] = 3, ["z"] = 4, ["name"] = "default:stonebrick"}, {["x"] = 6, ["y"] = 3, ["z"] = 6, ["name"] = "default:stonebrick"}, {["x"] = 6, ["y"] = 3, ["z"] = 7, ["name"] = "default:stonebrick"}, {["x"] = 6, ["y"] = 3, ["z"] = 9, ["name"] = "default:stonebrick"}, {["x"] = 6, ["y"] = 3, ["z"] = 11, ["name"] = "default:stonebrick"}, {["x"] = 6, ["y"] = 3, ["z"] = 17, ["name"] = "default:stonebrick"}, {["x"] = 6, ["y"] = 3, ["z"] = 19, ["name"] = "default:stonebrick"}, {["x"] = 6, ["y"] = 3, ["z"] = 24, ["name"] = "default:stonebrick"}, {["x"] = 6, ["y"] = 3, ["z"] = 25, ["name"] = "default:stonebrick"}, {["x"] = 6, ["y"] = 3, ["z"] = 28, ["name"] = "default:stonebrick"}, {["x"] = 6, ["y"] = 3, ["z"] = 29, ["name"] = "default:stonebrick"}, {["x"] = 6, ["y"] = 3, ["z"] = 31, ["name"] = "default:stonebrick"}, {["x"] = 6, ["y"] = 3, ["param1"] = 15, ["z"] = 35, ["name"] = "default:stonebrick"}, {["x"] = 6, ["y"] = 4, ["param1"] = 15, ["z"] = 1, ["name"] = "default:stonebrick"}, {["x"] = 6, ["y"] = 4, ["z"] = 4, ["name"] = "default:stonebrick"}, {["x"] = 6, ["y"] = 4, ["z"] = 6, ["name"] = "default:stonebrick"}, {["x"] = 6, ["y"] = 4, ["z"] = 7, ["name"] = "default:stonebrick"}, {["x"] = 6, ["y"] = 4, ["z"] = 9, ["name"] = "default:stonebrick"}, {["x"] = 6, ["y"] = 4, ["z"] = 11, ["name"] = "default:stonebrick"}, {["x"] = 6, ["y"] = 4, ["z"] = 17, ["name"] = "default:stonebrick"}, {["x"] = 6, ["y"] = 4, ["z"] = 19, ["name"] = "default:stonebrick"}, {["x"] = 6, ["y"] = 4, ["z"] = 24, ["name"] = "default:stonebrick"}, {["x"] = 6, ["y"] = 4, ["z"] = 25, ["name"] = "default:stonebrick"}, {["x"] = 6, ["y"] = 4, ["z"] = 28, ["name"] = "default:stonebrick"}, {["x"] = 6, ["y"] = 4, ["z"] = 29, ["name"] = "default:stonebrick"}, {["x"] = 6, ["y"] = 4, ["z"] = 31, ["name"] = "default:stonebrick"}, {["x"] = 6, ["y"] = 4, ["param1"] = 15, ["z"] = 35, ["name"] = "default:stonebrick"}, {["x"] = 6, ["y"] = 5, ["param1"] = 15, ["z"] = 1, ["name"] = "default:stonebrick"}, {["x"] = 6, ["y"] = 5, ["z"] = 4, ["name"] = "default:stonebrick"}, {["x"] = 6, ["y"] = 5, ["z"] = 6, ["name"] = "default:stonebrick"}, {["x"] = 6, ["y"] = 5, ["z"] = 7, ["name"] = "default:stonebrick"}, {["x"] = 6, ["y"] = 5, ["z"] = 9, ["name"] = "default:stonebrick"}, {["x"] = 6, ["y"] = 5, ["z"] = 11, ["name"] = "default:stonebrick"}, {["x"] = 6, ["y"] = 5, ["z"] = 17, ["name"] = "default:stonebrick"}, {["x"] = 6, ["y"] = 5, ["z"] = 19, ["name"] = "default:stonebrick"}, {["x"] = 6, ["y"] = 5, ["z"] = 24, ["name"] = "default:stonebrick"}, {["x"] = 6, ["y"] = 5, ["z"] = 25, ["name"] = "default:stonebrick"}, {["x"] = 6, ["y"] = 5, ["z"] = 28, ["name"] = "default:stonebrick"}, {["x"] = 6, ["y"] = 5, ["z"] = 29, ["name"] = "default:stonebrick"}, {["x"] = 6, ["y"] = 5, ["z"] = 31, ["name"] = "default:stonebrick"}, {["x"] = 6, ["y"] = 5, ["param1"] = 15, ["z"] = 35, ["name"] = "default:stonebrick"}, {["x"] = 6, ["y"] = 6, ["param1"] = 15, ["z"] = 1, ["name"] = "default:stonebrick"}, {["x"] = 6, ["y"] = 6, ["z"] = 4, ["name"] = "default:stonebrick"}, {["x"] = 6, ["y"] = 6, ["z"] = 6, ["name"] = "default:stonebrick"}, {["x"] = 6, ["y"] = 6, ["z"] = 7, ["name"] = "default:stonebrick"}, {["x"] = 6, ["y"] = 6, ["z"] = 9, ["name"] = "default:stonebrick"}, {["x"] = 6, ["y"] = 6, ["z"] = 11, ["name"] = "default:stonebrick"}, {["x"] = 6, ["y"] = 6, ["z"] = 17, ["name"] = "default:stonebrick"}, {["x"] = 6, ["y"] = 6, ["z"] = 19, ["name"] = "default:stonebrick"}, {["x"] = 6, ["y"] = 6, ["z"] = 24, ["name"] = "default:stonebrick"}, {["x"] = 6, ["y"] = 6, ["z"] = 25, ["name"] = "default:stonebrick"}, {["x"] = 6, ["y"] = 6, ["z"] = 28, ["name"] = "default:stonebrick"}, {["x"] = 6, ["y"] = 6, ["z"] = 29, ["name"] = "default:stonebrick"}, {["x"] = 6, ["y"] = 6, ["z"] = 31, ["name"] = "default:stonebrick"}, {["x"] = 6, ["y"] = 6, ["param1"] = 15, ["z"] = 35, ["name"] = "default:stonebrick"}, {["x"] = 6, ["y"] = 7, ["param1"] = 15, ["z"] = 1, ["name"] = "default:stonebrick"}, {["x"] = 6, ["y"] = 7, ["z"] = 4, ["name"] = "default:stonebrick"}, {["x"] = 6, ["y"] = 7, ["z"] = 6, ["name"] = "default:stonebrick"}, {["x"] = 6, ["y"] = 7, ["z"] = 7, ["name"] = "default:stonebrick"}, {["x"] = 6, ["y"] = 7, ["z"] = 9, ["name"] = "default:stonebrick"}, {["x"] = 6, ["y"] = 7, ["z"] = 11, ["name"] = "default:stonebrick"}, {["x"] = 6, ["y"] = 7, ["z"] = 17, ["name"] = "default:stonebrick"}, {["x"] = 6, ["y"] = 7, ["z"] = 19, ["name"] = "default:stonebrick"}, {["x"] = 6, ["y"] = 7, ["z"] = 24, ["name"] = "default:stonebrick"}, {["x"] = 6, ["y"] = 7, ["z"] = 25, ["name"] = "default:stonebrick"}, {["x"] = 6, ["y"] = 7, ["z"] = 28, ["name"] = "default:stonebrick"}, {["x"] = 6, ["y"] = 7, ["z"] = 29, ["name"] = "default:stonebrick"}, {["x"] = 6, ["y"] = 7, ["z"] = 31, ["name"] = "default:stonebrick"}, {["x"] = 6, ["y"] = 7, ["param1"] = 15, ["z"] = 35, ["name"] = "default:stonebrick"}, {["x"] = 7, ["y"] = 2, ["z"] = 1, ["name"] = "default:dirt"}, {["x"] = 7, ["y"] = 2, ["param1"] = 15, ["z"] = 2, ["name"] = "default:dirt"}, {["x"] = 7, ["y"] = 2, ["param1"] = 15, ["z"] = 3, ["name"] = "default:dirt"}, {["x"] = 7, ["y"] = 2, ["param1"] = 15, ["z"] = 4, ["name"] = "default:dirt"}, {["x"] = 7, ["y"] = 2, ["param1"] = 15, ["z"] = 5, ["name"] = "default:dirt"}, {["x"] = 7, ["y"] = 2, ["param1"] = 15, ["z"] = 6, ["name"] = "default:dirt"}, {["x"] = 7, ["y"] = 2, ["param1"] = 15, ["z"] = 7, ["name"] = "default:dirt"}, {["x"] = 7, ["y"] = 2, ["param1"] = 15, ["z"] = 8, ["name"] = "default:dirt"}, {["x"] = 7, ["y"] = 2, ["param1"] = 15, ["z"] = 9, ["name"] = "default:dirt"}, {["x"] = 7, ["y"] = 2, ["param1"] = 15, ["z"] = 10, ["name"] = "default:dirt"}, {["x"] = 7, ["y"] = 2, ["param1"] = 15, ["z"] = 11, ["name"] = "default:dirt"}, {["x"] = 7, ["y"] = 2, ["param1"] = 15, ["z"] = 12, ["name"] = "default:dirt"}, {["x"] = 7, ["y"] = 2, ["param1"] = 15, ["z"] = 13, ["name"] = "default:dirt"}, {["x"] = 7, ["y"] = 2, ["param1"] = 15, ["z"] = 14, ["name"] = "default:dirt"}, {["x"] = 7, ["y"] = 2, ["param1"] = 15, ["z"] = 15, ["name"] = "default:dirt"}, {["x"] = 7, ["y"] = 2, ["param1"] = 15, ["z"] = 16, ["name"] = "default:dirt"}, {["x"] = 7, ["y"] = 2, ["param1"] = 15, ["z"] = 17, ["name"] = "default:dirt"}, {["x"] = 7, ["y"] = 2, ["param1"] = 15, ["z"] = 18, ["name"] = "default:dirt"}, {["x"] = 7, ["y"] = 2, ["param1"] = 15, ["z"] = 19, ["name"] = "default:dirt"}, {["x"] = 7, ["y"] = 2, ["param1"] = 15, ["z"] = 20, ["name"] = "default:dirt"}, {["x"] = 7, ["y"] = 2, ["param1"] = 15, ["z"] = 21, ["name"] = "default:dirt"}, {["x"] = 7, ["y"] = 2, ["param1"] = 15, ["z"] = 22, ["name"] = "default:dirt"}, {["x"] = 7, ["y"] = 2, ["param1"] = 15, ["z"] = 23, ["name"] = "default:dirt"}, {["x"] = 7, ["y"] = 2, ["param1"] = 15, ["z"] = 24, ["name"] = "default:dirt"}, {["x"] = 7, ["y"] = 2, ["param1"] = 15, ["z"] = 25, ["name"] = "default:dirt"}, {["x"] = 7, ["y"] = 2, ["param1"] = 15, ["z"] = 26, ["name"] = "default:dirt"}, {["x"] = 7, ["y"] = 2, ["param1"] = 15, ["z"] = 27, ["name"] = "default:dirt"}, {["x"] = 7, ["y"] = 2, ["param1"] = 15, ["z"] = 28, ["name"] = "default:dirt"}, {["x"] = 7, ["y"] = 2, ["param1"] = 15, ["z"] = 29, ["name"] = "default:dirt"}, {["x"] = 7, ["y"] = 2, ["param1"] = 15, ["z"] = 30, ["name"] = "default:dirt"}, {["x"] = 7, ["y"] = 2, ["param1"] = 15, ["z"] = 31, ["name"] = "default:dirt"}, {["x"] = 7, ["y"] = 2, ["param1"] = 15, ["z"] = 32, ["name"] = "default:dirt"}, {["x"] = 7, ["y"] = 2, ["param1"] = 15, ["z"] = 33, ["name"] = "default:dirt"}, {["x"] = 7, ["y"] = 2, ["param1"] = 15, ["z"] = 34, ["name"] = "default:dirt"}, {["x"] = 7, ["y"] = 2, ["z"] = 35, ["name"] = "default:dirt"}, {["x"] = 7, ["y"] = 3, ["param1"] = 15, ["z"] = 1, ["name"] = "default:stonebrick"}, {["x"] = 7, ["y"] = 3, ["z"] = 3, ["name"] = "default:stonebrick"}, {["x"] = 7, ["y"] = 3, ["z"] = 7, ["name"] = "default:stonebrick"}, {["x"] = 7, ["y"] = 3, ["z"] = 9, ["name"] = "default:stonebrick"}, {["x"] = 7, ["y"] = 3, ["z"] = 10, ["name"] = "default:stonebrick"}, {["x"] = 7, ["y"] = 3, ["z"] = 13, ["name"] = "default:stonebrick"}, {["x"] = 7, ["y"] = 3, ["z"] = 14, ["name"] = "default:stonebrick"}, {["x"] = 7, ["y"] = 3, ["z"] = 15, ["name"] = "default:stonebrick"}, {["x"] = 7, ["y"] = 3, ["z"] = 20, ["name"] = "default:stonebrick"}, {["x"] = 7, ["y"] = 3, ["z"] = 22, ["name"] = "default:stonebrick"}, {["x"] = 7, ["y"] = 3, ["z"] = 26, ["name"] = "default:stonebrick"}, {["x"] = 7, ["y"] = 3, ["z"] = 30, ["name"] = "default:stonebrick"}, {["x"] = 7, ["y"] = 3, ["z"] = 33, ["name"] = "default:stonebrick"}, {["x"] = 7, ["y"] = 3, ["param1"] = 15, ["z"] = 35, ["name"] = "default:stonebrick"}, {["x"] = 7, ["y"] = 4, ["param1"] = 15, ["z"] = 1, ["name"] = "default:stonebrick"}, {["x"] = 7, ["y"] = 4, ["z"] = 3, ["name"] = "default:stonebrick"}, {["x"] = 7, ["y"] = 4, ["z"] = 7, ["name"] = "default:stonebrick"}, {["x"] = 7, ["y"] = 4, ["z"] = 9, ["name"] = "default:stonebrick"}, {["x"] = 7, ["y"] = 4, ["z"] = 10, ["name"] = "default:stonebrick"}, {["x"] = 7, ["y"] = 4, ["z"] = 13, ["name"] = "default:stonebrick"}, {["x"] = 7, ["y"] = 4, ["z"] = 14, ["name"] = "default:stonebrick"}, {["x"] = 7, ["y"] = 4, ["z"] = 15, ["name"] = "default:stonebrick"}, {["x"] = 7, ["y"] = 4, ["z"] = 20, ["name"] = "default:stonebrick"}, {["x"] = 7, ["y"] = 4, ["z"] = 22, ["name"] = "default:stonebrick"}, {["x"] = 7, ["y"] = 4, ["z"] = 26, ["name"] = "default:stonebrick"}, {["x"] = 7, ["y"] = 4, ["z"] = 30, ["name"] = "default:stonebrick"}, {["x"] = 7, ["y"] = 4, ["z"] = 33, ["name"] = "default:stonebrick"}, {["x"] = 7, ["y"] = 4, ["param1"] = 15, ["z"] = 35, ["name"] = "default:stonebrick"}, {["x"] = 7, ["y"] = 5, ["param1"] = 15, ["z"] = 1, ["name"] = "default:stonebrick"}, {["x"] = 7, ["y"] = 5, ["z"] = 3, ["name"] = "default:stonebrick"}, {["x"] = 7, ["y"] = 5, ["z"] = 7, ["name"] = "default:stonebrick"}, {["x"] = 7, ["y"] = 5, ["z"] = 9, ["name"] = "default:stonebrick"}, {["x"] = 7, ["y"] = 5, ["z"] = 10, ["name"] = "default:stonebrick"}, {["x"] = 7, ["y"] = 5, ["z"] = 13, ["name"] = "default:stonebrick"}, {["x"] = 7, ["y"] = 5, ["z"] = 14, ["name"] = "default:stonebrick"}, {["x"] = 7, ["y"] = 5, ["z"] = 15, ["name"] = "default:stonebrick"}, {["x"] = 7, ["y"] = 5, ["z"] = 20, ["name"] = "default:stonebrick"}, {["x"] = 7, ["y"] = 5, ["z"] = 22, ["name"] = "default:stonebrick"}, {["x"] = 7, ["y"] = 5, ["z"] = 26, ["name"] = "default:stonebrick"}, {["x"] = 7, ["y"] = 5, ["z"] = 30, ["name"] = "default:stonebrick"}, {["x"] = 7, ["y"] = 5, ["z"] = 33, ["name"] = "default:stonebrick"}, {["x"] = 7, ["y"] = 5, ["param1"] = 15, ["z"] = 35, ["name"] = "default:stonebrick"}, {["x"] = 7, ["y"] = 6, ["param1"] = 15, ["z"] = 1, ["name"] = "default:stonebrick"}, {["x"] = 7, ["y"] = 6, ["z"] = 3, ["name"] = "default:stonebrick"}, {["x"] = 7, ["y"] = 6, ["z"] = 7, ["name"] = "default:stonebrick"}, {["x"] = 7, ["y"] = 6, ["z"] = 9, ["name"] = "default:stonebrick"}, {["x"] = 7, ["y"] = 6, ["z"] = 10, ["name"] = "default:stonebrick"}, {["x"] = 7, ["y"] = 6, ["z"] = 13, ["name"] = "default:stonebrick"}, {["x"] = 7, ["y"] = 6, ["z"] = 14, ["name"] = "default:stonebrick"}, {["x"] = 7, ["y"] = 6, ["z"] = 15, ["name"] = "default:stonebrick"}, {["x"] = 7, ["y"] = 6, ["z"] = 20, ["name"] = "default:stonebrick"}, {["x"] = 7, ["y"] = 6, ["z"] = 22, ["name"] = "default:stonebrick"}, {["x"] = 7, ["y"] = 6, ["z"] = 26, ["name"] = "default:stonebrick"}, {["x"] = 7, ["y"] = 6, ["z"] = 30, ["name"] = "default:stonebrick"}, {["x"] = 7, ["y"] = 6, ["z"] = 33, ["name"] = "default:stonebrick"}, {["x"] = 7, ["y"] = 6, ["param1"] = 15, ["z"] = 35, ["name"] = "default:stonebrick"}, {["x"] = 7, ["y"] = 7, ["param1"] = 15, ["z"] = 1, ["name"] = "default:stonebrick"}, {["x"] = 7, ["y"] = 7, ["z"] = 3, ["name"] = "default:stonebrick"}, {["x"] = 7, ["y"] = 7, ["z"] = 7, ["name"] = "default:stonebrick"}, {["x"] = 7, ["y"] = 7, ["z"] = 9, ["name"] = "default:stonebrick"}, {["x"] = 7, ["y"] = 7, ["z"] = 10, ["name"] = "default:stonebrick"}, {["x"] = 7, ["y"] = 7, ["z"] = 13, ["name"] = "default:stonebrick"}, {["x"] = 7, ["y"] = 7, ["z"] = 14, ["name"] = "default:stonebrick"}, {["x"] = 7, ["y"] = 7, ["z"] = 15, ["name"] = "default:stonebrick"}, {["x"] = 7, ["y"] = 7, ["z"] = 20, ["name"] = "default:stonebrick"}, {["x"] = 7, ["y"] = 7, ["z"] = 22, ["name"] = "default:stonebrick"}, {["x"] = 7, ["y"] = 7, ["z"] = 26, ["name"] = "default:stonebrick"}, {["x"] = 7, ["y"] = 7, ["z"] = 30, ["name"] = "default:stonebrick"}, {["x"] = 7, ["y"] = 7, ["z"] = 33, ["name"] = "default:stonebrick"}, {["x"] = 7, ["y"] = 7, ["param1"] = 15, ["z"] = 35, ["name"] = "default:stonebrick"}, {["x"] = 8, ["y"] = 2, ["z"] = 1, ["name"] = "default:dirt"}, {["x"] = 8, ["y"] = 2, ["param1"] = 15, ["z"] = 2, ["name"] = "default:dirt"}, {["x"] = 8, ["y"] = 2, ["param1"] = 15, ["z"] = 3, ["name"] = "default:dirt"}, {["x"] = 8, ["y"] = 2, ["param1"] = 15, ["z"] = 4, ["name"] = "default:dirt"}, {["x"] = 8, ["y"] = 2, ["param1"] = 15, ["z"] = 5, ["name"] = "default:dirt"}, {["x"] = 8, ["y"] = 2, ["param1"] = 15, ["z"] = 6, ["name"] = "default:dirt"}, {["x"] = 8, ["y"] = 2, ["param1"] = 15, ["z"] = 7, ["name"] = "default:dirt"}, {["x"] = 8, ["y"] = 2, ["param1"] = 15, ["z"] = 8, ["name"] = "default:dirt"}, {["x"] = 8, ["y"] = 2, ["param1"] = 15, ["z"] = 9, ["name"] = "default:dirt"}, {["x"] = 8, ["y"] = 2, ["param1"] = 15, ["z"] = 10, ["name"] = "default:dirt"}, {["x"] = 8, ["y"] = 2, ["param1"] = 15, ["z"] = 11, ["name"] = "default:dirt"}, {["x"] = 8, ["y"] = 2, ["param1"] = 15, ["z"] = 12, ["name"] = "default:dirt"}, {["x"] = 8, ["y"] = 2, ["param1"] = 15, ["z"] = 13, ["name"] = "default:dirt"}, {["x"] = 8, ["y"] = 2, ["param1"] = 15, ["z"] = 14, ["name"] = "default:dirt"}, {["x"] = 8, ["y"] = 2, ["param1"] = 15, ["z"] = 15, ["name"] = "default:dirt"}, {["x"] = 8, ["y"] = 2, ["param1"] = 15, ["z"] = 16, ["name"] = "default:dirt"}, {["x"] = 8, ["y"] = 2, ["param1"] = 15, ["z"] = 17, ["name"] = "default:dirt"}, {["x"] = 8, ["y"] = 2, ["param1"] = 15, ["z"] = 18, ["name"] = "default:dirt"}, {["x"] = 8, ["y"] = 2, ["param1"] = 15, ["z"] = 19, ["name"] = "default:dirt"}, {["x"] = 8, ["y"] = 2, ["param1"] = 15, ["z"] = 20, ["name"] = "default:dirt"}, {["x"] = 8, ["y"] = 2, ["param1"] = 15, ["z"] = 21, ["name"] = "default:dirt"}, {["x"] = 8, ["y"] = 2, ["param1"] = 15, ["z"] = 22, ["name"] = "default:dirt"}, {["x"] = 8, ["y"] = 2, ["param1"] = 15, ["z"] = 23, ["name"] = "default:dirt"}, {["x"] = 8, ["y"] = 2, ["param1"] = 15, ["z"] = 24, ["name"] = "default:dirt"}, {["x"] = 8, ["y"] = 2, ["param1"] = 15, ["z"] = 25, ["name"] = "default:dirt"}, {["x"] = 8, ["y"] = 2, ["param1"] = 15, ["z"] = 26, ["name"] = "default:dirt"}, {["x"] = 8, ["y"] = 2, ["param1"] = 15, ["z"] = 27, ["name"] = "default:dirt"}, {["x"] = 8, ["y"] = 2, ["param1"] = 15, ["z"] = 28, ["name"] = "default:dirt"}, {["x"] = 8, ["y"] = 2, ["param1"] = 15, ["z"] = 29, ["name"] = "default:dirt"}, {["x"] = 8, ["y"] = 2, ["param1"] = 15, ["z"] = 30, ["name"] = "default:dirt"}, {["x"] = 8, ["y"] = 2, ["param1"] = 15, ["z"] = 31, ["name"] = "default:dirt"}, {["x"] = 8, ["y"] = 2, ["param1"] = 15, ["z"] = 32, ["name"] = "default:dirt"}, {["x"] = 8, ["y"] = 2, ["param1"] = 15, ["z"] = 33, ["name"] = "default:dirt"}, {["x"] = 8, ["y"] = 2, ["param1"] = 15, ["z"] = 34, ["name"] = "default:dirt"}, {["x"] = 8, ["y"] = 2, ["z"] = 35, ["name"] = "default:dirt"}, {["x"] = 8, ["y"] = 3, ["param1"] = 15, ["z"] = 1, ["name"] = "default:stonebrick"}, {["x"] = 8, ["y"] = 3, ["z"] = 3, ["name"] = "default:stonebrick"}, {["x"] = 8, ["y"] = 3, ["z"] = 5, ["name"] = "default:stonebrick"}, {["x"] = 8, ["y"] = 3, ["z"] = 11, ["name"] = "default:stonebrick"}, {["x"] = 8, ["y"] = 3, ["z"] = 12, ["name"] = "default:stonebrick"}, {["x"] = 8, ["y"] = 3, ["z"] = 16, ["name"] = "default:stonebrick"}, {["x"] = 8, ["y"] = 3, ["z"] = 17, ["name"] = "default:stonebrick"}, {["x"] = 8, ["y"] = 3, ["z"] = 18, ["name"] = "default:stonebrick"}, {["x"] = 8, ["y"] = 3, ["z"] = 20, ["name"] = "default:stonebrick"}, {["x"] = 8, ["y"] = 3, ["z"] = 23, ["name"] = "default:stonebrick"}, {["x"] = 8, ["y"] = 3, ["z"] = 24, ["name"] = "default:stonebrick"}, {["x"] = 8, ["y"] = 3, ["z"] = 26, ["name"] = "default:stonebrick"}, {["x"] = 8, ["y"] = 3, ["z"] = 28, ["name"] = "default:stonebrick"}, {["x"] = 8, ["y"] = 3, ["z"] = 32, ["name"] = "default:stonebrick"}, {["x"] = 8, ["y"] = 3, ["param1"] = 15, ["z"] = 35, ["name"] = "default:stonebrick"}, {["x"] = 8, ["y"] = 4, ["param1"] = 15, ["z"] = 1, ["name"] = "default:stonebrick"}, {["x"] = 8, ["y"] = 4, ["z"] = 3, ["name"] = "default:stonebrick"}, {["x"] = 8, ["y"] = 4, ["z"] = 5, ["name"] = "default:stonebrick"}, {["x"] = 8, ["y"] = 4, ["z"] = 11, ["name"] = "default:stonebrick"}, {["x"] = 8, ["y"] = 4, ["z"] = 12, ["name"] = "default:stonebrick"}, {["x"] = 8, ["y"] = 4, ["z"] = 16, ["name"] = "default:stonebrick"}, {["x"] = 8, ["y"] = 4, ["z"] = 17, ["name"] = "default:stonebrick"}, {["x"] = 8, ["y"] = 4, ["z"] = 18, ["name"] = "default:stonebrick"}, {["x"] = 8, ["y"] = 4, ["z"] = 20, ["name"] = "default:stonebrick"}, {["x"] = 8, ["y"] = 4, ["z"] = 23, ["name"] = "default:stonebrick"}, {["x"] = 8, ["y"] = 4, ["z"] = 24, ["name"] = "default:stonebrick"}, {["x"] = 8, ["y"] = 4, ["z"] = 26, ["name"] = "default:stonebrick"}, {["x"] = 8, ["y"] = 4, ["z"] = 28, ["name"] = "default:stonebrick"}, {["x"] = 8, ["y"] = 4, ["z"] = 32, ["name"] = "default:stonebrick"}, {["x"] = 8, ["y"] = 4, ["param1"] = 15, ["z"] = 35, ["name"] = "default:stonebrick"}, {["x"] = 8, ["y"] = 5, ["param1"] = 15, ["z"] = 1, ["name"] = "default:stonebrick"}, {["x"] = 8, ["y"] = 5, ["z"] = 3, ["name"] = "default:stonebrick"}, {["x"] = 8, ["y"] = 5, ["z"] = 5, ["name"] = "default:stonebrick"}, {["x"] = 8, ["y"] = 5, ["z"] = 11, ["name"] = "default:stonebrick"}, {["x"] = 8, ["y"] = 5, ["z"] = 12, ["name"] = "default:stonebrick"}, {["x"] = 8, ["y"] = 5, ["z"] = 16, ["name"] = "default:stonebrick"}, {["x"] = 8, ["y"] = 5, ["z"] = 17, ["name"] = "default:stonebrick"}, {["x"] = 8, ["y"] = 5, ["z"] = 18, ["name"] = "default:stonebrick"}, {["x"] = 8, ["y"] = 5, ["z"] = 20, ["name"] = "default:stonebrick"}, {["x"] = 8, ["y"] = 5, ["z"] = 23, ["name"] = "default:stonebrick"}, {["x"] = 8, ["y"] = 5, ["z"] = 24, ["name"] = "default:stonebrick"}, {["x"] = 8, ["y"] = 5, ["z"] = 26, ["name"] = "default:stonebrick"}, {["x"] = 8, ["y"] = 5, ["z"] = 28, ["name"] = "default:stonebrick"}, {["x"] = 8, ["y"] = 5, ["z"] = 32, ["name"] = "default:stonebrick"}, {["x"] = 8, ["y"] = 5, ["param1"] = 15, ["z"] = 35, ["name"] = "default:stonebrick"}, {["x"] = 8, ["y"] = 6, ["param1"] = 15, ["z"] = 1, ["name"] = "default:stonebrick"}, {["x"] = 8, ["y"] = 6, ["z"] = 3, ["name"] = "default:stonebrick"}, {["x"] = 8, ["y"] = 6, ["z"] = 5, ["name"] = "default:stonebrick"}, {["x"] = 8, ["y"] = 6, ["z"] = 11, ["name"] = "default:stonebrick"}, {["x"] = 8, ["y"] = 6, ["z"] = 12, ["name"] = "default:stonebrick"}, {["x"] = 8, ["y"] = 6, ["z"] = 16, ["name"] = "default:stonebrick"}, {["x"] = 8, ["y"] = 6, ["z"] = 17, ["name"] = "default:stonebrick"}, {["x"] = 8, ["y"] = 6, ["z"] = 18, ["name"] = "default:stonebrick"}, {["x"] = 8, ["y"] = 6, ["z"] = 20, ["name"] = "default:stonebrick"}, {["x"] = 8, ["y"] = 6, ["z"] = 23, ["name"] = "default:stonebrick"}, {["x"] = 8, ["y"] = 6, ["z"] = 24, ["name"] = "default:stonebrick"}, {["x"] = 8, ["y"] = 6, ["z"] = 26, ["name"] = "default:stonebrick"}, {["x"] = 8, ["y"] = 6, ["z"] = 28, ["name"] = "default:stonebrick"}, {["x"] = 8, ["y"] = 6, ["z"] = 32, ["name"] = "default:stonebrick"}, {["x"] = 8, ["y"] = 6, ["param1"] = 15, ["z"] = 35, ["name"] = "default:stonebrick"}, {["x"] = 8, ["y"] = 7, ["param1"] = 15, ["z"] = 1, ["name"] = "default:stonebrick"}, {["x"] = 8, ["y"] = 7, ["z"] = 3, ["name"] = "default:stonebrick"}, {["x"] = 8, ["y"] = 7, ["z"] = 5, ["name"] = "default:stonebrick"}, {["x"] = 8, ["y"] = 7, ["z"] = 11, ["name"] = "default:stonebrick"}, {["x"] = 8, ["y"] = 7, ["z"] = 12, ["name"] = "default:stonebrick"}, {["x"] = 8, ["y"] = 7, ["z"] = 16, ["name"] = "default:stonebrick"}, {["x"] = 8, ["y"] = 7, ["z"] = 17, ["name"] = "default:stonebrick"}, {["x"] = 8, ["y"] = 7, ["z"] = 18, ["name"] = "default:stonebrick"}, {["x"] = 8, ["y"] = 7, ["z"] = 20, ["name"] = "default:stonebrick"}, {["x"] = 8, ["y"] = 7, ["z"] = 23, ["name"] = "default:stonebrick"}, {["x"] = 8, ["y"] = 7, ["z"] = 24, ["name"] = "default:stonebrick"}, {["x"] = 8, ["y"] = 7, ["z"] = 26, ["name"] = "default:stonebrick"}, {["x"] = 8, ["y"] = 7, ["z"] = 28, ["name"] = "default:stonebrick"}, {["x"] = 8, ["y"] = 7, ["z"] = 32, ["name"] = "default:stonebrick"}, {["x"] = 8, ["y"] = 7, ["param1"] = 15, ["z"] = 35, ["name"] = "default:stonebrick"}, {["x"] = 9, ["y"] = 2, ["z"] = 1, ["name"] = "default:dirt"}, {["x"] = 9, ["y"] = 2, ["param1"] = 15, ["z"] = 2, ["name"] = "default:dirt"}, {["x"] = 9, ["y"] = 2, ["param1"] = 15, ["z"] = 3, ["name"] = "default:dirt"}, {["x"] = 9, ["y"] = 2, ["param1"] = 15, ["z"] = 4, ["name"] = "default:dirt"}, {["x"] = 9, ["y"] = 2, ["param1"] = 15, ["z"] = 5, ["name"] = "default:dirt"}, {["x"] = 9, ["y"] = 2, ["param1"] = 15, ["z"] = 6, ["name"] = "default:dirt"}, {["x"] = 9, ["y"] = 2, ["param1"] = 15, ["z"] = 7, ["name"] = "default:dirt"}, {["x"] = 9, ["y"] = 2, ["param1"] = 15, ["z"] = 8, ["name"] = "default:dirt"}, {["x"] = 9, ["y"] = 2, ["param1"] = 15, ["z"] = 9, ["name"] = "default:dirt"}, {["x"] = 9, ["y"] = 2, ["param1"] = 15, ["z"] = 10, ["name"] = "default:dirt"}, {["x"] = 9, ["y"] = 2, ["param1"] = 15, ["z"] = 11, ["name"] = "default:dirt"}, {["x"] = 9, ["y"] = 2, ["param1"] = 15, ["z"] = 12, ["name"] = "default:dirt"}, {["x"] = 9, ["y"] = 2, ["param1"] = 15, ["z"] = 13, ["name"] = "default:dirt"}, {["x"] = 9, ["y"] = 2, ["param1"] = 15, ["z"] = 14, ["name"] = "default:dirt"}, {["x"] = 9, ["y"] = 2, ["param1"] = 15, ["z"] = 15, ["name"] = "default:dirt"}, {["x"] = 9, ["y"] = 2, ["param1"] = 15, ["z"] = 16, ["name"] = "default:dirt"}, {["x"] = 9, ["y"] = 2, ["param1"] = 15, ["z"] = 17, ["name"] = "default:dirt"}, {["x"] = 9, ["y"] = 2, ["param1"] = 15, ["z"] = 18, ["name"] = "default:dirt"}, {["x"] = 9, ["y"] = 2, ["param1"] = 15, ["z"] = 19, ["name"] = "default:dirt"}, {["x"] = 9, ["y"] = 2, ["param1"] = 15, ["z"] = 20, ["name"] = "default:dirt"}, {["x"] = 9, ["y"] = 2, ["param1"] = 15, ["z"] = 21, ["name"] = "default:dirt"}, {["x"] = 9, ["y"] = 2, ["param1"] = 15, ["z"] = 22, ["name"] = "default:dirt"}, {["x"] = 9, ["y"] = 2, ["param1"] = 15, ["z"] = 23, ["name"] = "default:dirt"}, {["x"] = 9, ["y"] = 2, ["param1"] = 15, ["z"] = 24, ["name"] = "default:dirt"}, {["x"] = 9, ["y"] = 2, ["param1"] = 15, ["z"] = 25, ["name"] = "default:dirt"}, {["x"] = 9, ["y"] = 2, ["param1"] = 15, ["z"] = 26, ["name"] = "default:dirt"}, {["x"] = 9, ["y"] = 2, ["param1"] = 15, ["z"] = 27, ["name"] = "default:dirt"}, {["x"] = 9, ["y"] = 2, ["param1"] = 15, ["z"] = 28, ["name"] = "default:dirt"}, {["x"] = 9, ["y"] = 2, ["param1"] = 15, ["z"] = 29, ["name"] = "default:dirt"}, {["x"] = 9, ["y"] = 2, ["param1"] = 15, ["z"] = 30, ["name"] = "default:dirt"}, {["x"] = 9, ["y"] = 2, ["param1"] = 15, ["z"] = 31, ["name"] = "default:dirt"}, {["x"] = 9, ["y"] = 2, ["param1"] = 15, ["z"] = 32, ["name"] = "default:dirt"}, {["x"] = 9, ["y"] = 2, ["param1"] = 15, ["z"] = 33, ["name"] = "default:dirt"}, {["x"] = 9, ["y"] = 2, ["param1"] = 15, ["z"] = 34, ["name"] = "default:dirt"}, {["x"] = 9, ["y"] = 2, ["z"] = 35, ["name"] = "default:dirt"}, {["x"] = 9, ["y"] = 3, ["param1"] = 15, ["z"] = 1, ["name"] = "default:stonebrick"}, {["x"] = 9, ["y"] = 3, ["z"] = 3, ["name"] = "default:stonebrick"}, {["x"] = 9, ["y"] = 3, ["z"] = 4, ["name"] = "default:stonebrick"}, {["x"] = 9, ["y"] = 3, ["z"] = 5, ["name"] = "default:stonebrick"}, {["x"] = 9, ["y"] = 3, ["z"] = 7, ["name"] = "default:stonebrick"}, {["x"] = 9, ["y"] = 3, ["z"] = 8, ["name"] = "default:stonebrick"}, {["x"] = 9, ["y"] = 3, ["z"] = 9, ["name"] = "default:stonebrick"}, {["x"] = 9, ["y"] = 3, ["z"] = 11, ["name"] = "default:stonebrick"}, {["x"] = 9, ["y"] = 3, ["z"] = 14, ["name"] = "default:stonebrick"}, {["x"] = 9, ["y"] = 3, ["z"] = 17, ["name"] = "default:stonebrick"}, {["x"] = 9, ["y"] = 3, ["z"] = 20, ["name"] = "default:stonebrick"}, {["x"] = 9, ["y"] = 3, ["z"] = 21, ["name"] = "default:stonebrick"}, {["x"] = 9, ["y"] = 3, ["z"] = 28, ["name"] = "default:stonebrick"}, {["x"] = 9, ["y"] = 3, ["z"] = 29, ["name"] = "default:stonebrick"}, {["x"] = 9, ["y"] = 3, ["z"] = 31, ["name"] = "default:stonebrick"}, {["x"] = 9, ["y"] = 3, ["z"] = 34, ["name"] = "default:stonebrick"}, {["x"] = 9, ["y"] = 3, ["param1"] = 15, ["z"] = 35, ["name"] = "default:stonebrick"}, {["x"] = 9, ["y"] = 4, ["param1"] = 15, ["z"] = 1, ["name"] = "default:stonebrick"}, {["x"] = 9, ["y"] = 4, ["z"] = 3, ["name"] = "default:stonebrick"}, {["x"] = 9, ["y"] = 4, ["z"] = 4, ["name"] = "default:stonebrick"}, {["x"] = 9, ["y"] = 4, ["z"] = 5, ["name"] = "default:stonebrick"}, {["x"] = 9, ["y"] = 4, ["z"] = 7, ["name"] = "default:stonebrick"}, {["x"] = 9, ["y"] = 4, ["z"] = 8, ["name"] = "default:stonebrick"}, {["x"] = 9, ["y"] = 4, ["z"] = 9, ["name"] = "default:stonebrick"}, {["x"] = 9, ["y"] = 4, ["z"] = 11, ["name"] = "default:stonebrick"}, {["x"] = 9, ["y"] = 4, ["z"] = 14, ["name"] = "default:stonebrick"}, {["x"] = 9, ["y"] = 4, ["z"] = 17, ["name"] = "default:stonebrick"}, {["x"] = 9, ["y"] = 4, ["z"] = 20, ["name"] = "default:stonebrick"}, {["x"] = 9, ["y"] = 4, ["z"] = 21, ["name"] = "default:stonebrick"}, {["x"] = 9, ["y"] = 4, ["z"] = 28, ["name"] = "default:stonebrick"}, {["x"] = 9, ["y"] = 4, ["z"] = 29, ["name"] = "default:stonebrick"}, {["x"] = 9, ["y"] = 4, ["z"] = 31, ["name"] = "default:stonebrick"}, {["x"] = 9, ["y"] = 4, ["z"] = 34, ["name"] = "default:stonebrick"}, {["x"] = 9, ["y"] = 4, ["param1"] = 15, ["z"] = 35, ["name"] = "default:stonebrick"}, {["x"] = 9, ["y"] = 5, ["param1"] = 15, ["z"] = 1, ["name"] = "default:stonebrick"}, {["x"] = 9, ["y"] = 5, ["z"] = 3, ["name"] = "default:stonebrick"}, {["x"] = 9, ["y"] = 5, ["z"] = 4, ["name"] = "default:stonebrick"}, {["x"] = 9, ["y"] = 5, ["z"] = 5, ["name"] = "default:stonebrick"}, {["x"] = 9, ["y"] = 5, ["z"] = 7, ["name"] = "default:stonebrick"}, {["x"] = 9, ["y"] = 5, ["z"] = 8, ["name"] = "default:stonebrick"}, {["x"] = 9, ["y"] = 5, ["z"] = 9, ["name"] = "default:stonebrick"}, {["x"] = 9, ["y"] = 5, ["z"] = 11, ["name"] = "default:stonebrick"}, {["x"] = 9, ["y"] = 5, ["z"] = 14, ["name"] = "default:stonebrick"}, {["x"] = 9, ["y"] = 5, ["z"] = 17, ["name"] = "default:stonebrick"}, {["x"] = 9, ["y"] = 5, ["z"] = 20, ["name"] = "default:stonebrick"}, {["x"] = 9, ["y"] = 5, ["z"] = 21, ["name"] = "default:stonebrick"}, {["x"] = 9, ["y"] = 5, ["z"] = 28, ["name"] = "default:stonebrick"}, {["x"] = 9, ["y"] = 5, ["z"] = 29, ["name"] = "default:stonebrick"}, {["x"] = 9, ["y"] = 5, ["z"] = 31, ["name"] = "default:stonebrick"}, {["x"] = 9, ["y"] = 5, ["z"] = 34, ["name"] = "default:stonebrick"}, {["x"] = 9, ["y"] = 5, ["param1"] = 15, ["z"] = 35, ["name"] = "default:stonebrick"}, {["x"] = 9, ["y"] = 6, ["param1"] = 15, ["z"] = 1, ["name"] = "default:stonebrick"}, {["x"] = 9, ["y"] = 6, ["z"] = 3, ["name"] = "default:stonebrick"}, {["x"] = 9, ["y"] = 6, ["z"] = 4, ["name"] = "default:stonebrick"}, {["x"] = 9, ["y"] = 6, ["z"] = 5, ["name"] = "default:stonebrick"}, {["x"] = 9, ["y"] = 6, ["z"] = 7, ["name"] = "default:stonebrick"}, {["x"] = 9, ["y"] = 6, ["z"] = 8, ["name"] = "default:stonebrick"}, {["x"] = 9, ["y"] = 6, ["z"] = 9, ["name"] = "default:stonebrick"}, {["x"] = 9, ["y"] = 6, ["z"] = 11, ["name"] = "default:stonebrick"}, {["x"] = 9, ["y"] = 6, ["z"] = 14, ["name"] = "default:stonebrick"}, {["x"] = 9, ["y"] = 6, ["z"] = 17, ["name"] = "default:stonebrick"}, {["x"] = 9, ["y"] = 6, ["z"] = 20, ["name"] = "default:stonebrick"}, {["x"] = 9, ["y"] = 6, ["z"] = 21, ["name"] = "default:stonebrick"}, {["x"] = 9, ["y"] = 6, ["z"] = 28, ["name"] = "default:stonebrick"}, {["x"] = 9, ["y"] = 6, ["z"] = 29, ["name"] = "default:stonebrick"}, {["x"] = 9, ["y"] = 6, ["z"] = 31, ["name"] = "default:stonebrick"}, {["x"] = 9, ["y"] = 6, ["z"] = 34, ["name"] = "default:stonebrick"}, {["x"] = 9, ["y"] = 6, ["param1"] = 15, ["z"] = 35, ["name"] = "default:stonebrick"}, {["x"] = 9, ["y"] = 7, ["param1"] = 15, ["z"] = 1, ["name"] = "default:stonebrick"}, {["x"] = 9, ["y"] = 7, ["z"] = 3, ["name"] = "default:stonebrick"}, {["x"] = 9, ["y"] = 7, ["z"] = 4, ["name"] = "default:stonebrick"}, {["x"] = 9, ["y"] = 7, ["z"] = 5, ["name"] = "default:stonebrick"}, {["x"] = 9, ["y"] = 7, ["z"] = 7, ["name"] = "default:stonebrick"}, {["x"] = 9, ["y"] = 7, ["z"] = 8, ["name"] = "default:stonebrick"}, {["x"] = 9, ["y"] = 7, ["z"] = 9, ["name"] = "default:stonebrick"}, {["x"] = 9, ["y"] = 7, ["z"] = 11, ["name"] = "default:stonebrick"}, {["x"] = 9, ["y"] = 7, ["z"] = 14, ["name"] = "default:stonebrick"}, {["x"] = 9, ["y"] = 7, ["z"] = 17, ["name"] = "default:stonebrick"}, {["x"] = 9, ["y"] = 7, ["z"] = 20, ["name"] = "default:stonebrick"}, {["x"] = 9, ["y"] = 7, ["z"] = 21, ["name"] = "default:stonebrick"}, {["x"] = 9, ["y"] = 7, ["z"] = 28, ["name"] = "default:stonebrick"}, {["x"] = 9, ["y"] = 7, ["z"] = 29, ["name"] = "default:stonebrick"}, {["x"] = 9, ["y"] = 7, ["z"] = 31, ["name"] = "default:stonebrick"}, {["x"] = 9, ["y"] = 7, ["z"] = 34, ["name"] = "default:stonebrick"}, {["x"] = 9, ["y"] = 7, ["param1"] = 15, ["z"] = 35, ["name"] = "default:stonebrick"}, {["x"] = 10, ["y"] = 2, ["z"] = 1, ["name"] = "default:dirt"}, {["x"] = 10, ["y"] = 2, ["param1"] = 15, ["z"] = 2, ["name"] = "default:dirt"}, {["x"] = 10, ["y"] = 2, ["param1"] = 15, ["z"] = 3, ["name"] = "default:dirt"}, {["x"] = 10, ["y"] = 2, ["param1"] = 15, ["z"] = 4, ["name"] = "default:dirt"}, {["x"] = 10, ["y"] = 2, ["param1"] = 15, ["z"] = 5, ["name"] = "default:dirt"}, {["x"] = 10, ["y"] = 2, ["param1"] = 15, ["z"] = 6, ["name"] = "default:dirt"}, {["x"] = 10, ["y"] = 2, ["param1"] = 15, ["z"] = 7, ["name"] = "default:dirt"}, {["x"] = 10, ["y"] = 2, ["param1"] = 15, ["z"] = 8, ["name"] = "default:dirt"}, {["x"] = 10, ["y"] = 2, ["param1"] = 15, ["z"] = 9, ["name"] = "default:dirt"}, {["x"] = 10, ["y"] = 2, ["param1"] = 15, ["z"] = 10, ["name"] = "default:dirt"}, {["x"] = 10, ["y"] = 2, ["param1"] = 15, ["z"] = 11, ["name"] = "default:dirt"}, {["x"] = 10, ["y"] = 2, ["param1"] = 15, ["z"] = 12, ["name"] = "default:dirt"}, {["x"] = 10, ["y"] = 2, ["param1"] = 15, ["z"] = 13, ["name"] = "default:dirt"}, {["x"] = 10, ["y"] = 2, ["param1"] = 15, ["z"] = 14, ["name"] = "default:dirt"}, {["x"] = 10, ["y"] = 2, ["param1"] = 15, ["z"] = 15, ["name"] = "default:dirt"}, {["x"] = 10, ["y"] = 2, ["param1"] = 15, ["z"] = 16, ["name"] = "default:dirt"}, {["x"] = 10, ["y"] = 2, ["param1"] = 15, ["z"] = 17, ["name"] = "default:dirt"}, {["x"] = 10, ["y"] = 2, ["param1"] = 15, ["z"] = 18, ["name"] = "default:dirt"}, {["x"] = 10, ["y"] = 2, ["param1"] = 15, ["z"] = 19, ["name"] = "default:dirt"}, {["x"] = 10, ["y"] = 2, ["param1"] = 15, ["z"] = 20, ["name"] = "default:dirt"}, {["x"] = 10, ["y"] = 2, ["param1"] = 15, ["z"] = 21, ["name"] = "default:dirt"}, {["x"] = 10, ["y"] = 2, ["param1"] = 15, ["z"] = 22, ["name"] = "default:dirt"}, {["x"] = 10, ["y"] = 2, ["param1"] = 15, ["z"] = 23, ["name"] = "default:dirt"}, {["x"] = 10, ["y"] = 2, ["param1"] = 15, ["z"] = 24, ["name"] = "default:dirt"}, {["x"] = 10, ["y"] = 2, ["param1"] = 15, ["z"] = 25, ["name"] = "default:dirt"}, {["x"] = 10, ["y"] = 2, ["param1"] = 15, ["z"] = 26, ["name"] = "default:dirt"}, {["x"] = 10, ["y"] = 2, ["param1"] = 15, ["z"] = 27, ["name"] = "default:dirt"}, {["x"] = 10, ["y"] = 2, ["param1"] = 15, ["z"] = 28, ["name"] = "default:dirt"}, {["x"] = 10, ["y"] = 2, ["param1"] = 15, ["z"] = 29, ["name"] = "default:dirt"}, {["x"] = 10, ["y"] = 2, ["param1"] = 15, ["z"] = 30, ["name"] = "default:dirt"}, {["x"] = 10, ["y"] = 2, ["param1"] = 15, ["z"] = 31, ["name"] = "default:dirt"}, {["x"] = 10, ["y"] = 2, ["param1"] = 15, ["z"] = 32, ["name"] = "default:dirt"}, {["x"] = 10, ["y"] = 2, ["param1"] = 15, ["z"] = 33, ["name"] = "default:dirt"}, {["x"] = 10, ["y"] = 2, ["param1"] = 15, ["z"] = 34, ["name"] = "default:dirt"}, {["x"] = 10, ["y"] = 2, ["z"] = 35, ["name"] = "default:dirt"}, {["x"] = 10, ["y"] = 3, ["param1"] = 15, ["z"] = 1, ["name"] = "default:stonebrick"}, {["x"] = 10, ["y"] = 3, ["z"] = 2, ["name"] = "default:stonebrick"}, {["x"] = 10, ["y"] = 3, ["z"] = 6, ["name"] = "default:stonebrick"}, {["x"] = 10, ["y"] = 3, ["z"] = 11, ["name"] = "default:stonebrick"}, {["x"] = 10, ["y"] = 3, ["z"] = 13, ["name"] = "default:stonebrick"}, {["x"] = 10, ["y"] = 3, ["z"] = 15, ["name"] = "default:stonebrick"}, {["x"] = 10, ["y"] = 3, ["z"] = 17, ["name"] = "default:stonebrick"}, {["x"] = 10, ["y"] = 3, ["z"] = 19, ["name"] = "default:stonebrick"}, {["x"] = 10, ["y"] = 3, ["z"] = 23, ["name"] = "default:stonebrick"}, {["x"] = 10, ["y"] = 3, ["z"] = 25, ["name"] = "default:stonebrick"}, {["x"] = 10, ["y"] = 3, ["z"] = 26, ["name"] = "default:stonebrick"}, {["x"] = 10, ["y"] = 3, ["z"] = 27, ["name"] = "default:stonebrick"}, {["x"] = 10, ["y"] = 3, ["z"] = 31, ["name"] = "default:stonebrick"}, {["x"] = 10, ["y"] = 3, ["z"] = 32, ["name"] = "default:stonebrick"}, {["x"] = 10, ["y"] = 3, ["param1"] = 15, ["z"] = 35, ["name"] = "default:stonebrick"}, {["x"] = 10, ["y"] = 4, ["param1"] = 15, ["z"] = 1, ["name"] = "default:stonebrick"}, {["x"] = 10, ["y"] = 4, ["z"] = 2, ["name"] = "default:stonebrick"}, {["x"] = 10, ["y"] = 4, ["z"] = 6, ["name"] = "default:stonebrick"}, {["x"] = 10, ["y"] = 4, ["z"] = 11, ["name"] = "default:stonebrick"}, {["x"] = 10, ["y"] = 4, ["z"] = 13, ["name"] = "default:stonebrick"}, {["x"] = 10, ["y"] = 4, ["z"] = 15, ["name"] = "default:stonebrick"}, {["x"] = 10, ["y"] = 4, ["z"] = 17, ["name"] = "default:stonebrick"}, {["x"] = 10, ["y"] = 4, ["z"] = 19, ["name"] = "default:stonebrick"}, {["x"] = 10, ["y"] = 4, ["z"] = 23, ["name"] = "default:stonebrick"}, {["x"] = 10, ["y"] = 4, ["z"] = 25, ["name"] = "default:stonebrick"}, {["x"] = 10, ["y"] = 4, ["z"] = 26, ["name"] = "default:stonebrick"}, {["x"] = 10, ["y"] = 4, ["z"] = 27, ["name"] = "default:stonebrick"}, {["x"] = 10, ["y"] = 4, ["z"] = 31, ["name"] = "default:stonebrick"}, {["x"] = 10, ["y"] = 4, ["z"] = 32, ["name"] = "default:stonebrick"}, {["x"] = 10, ["y"] = 4, ["param1"] = 15, ["z"] = 35, ["name"] = "default:stonebrick"}, {["x"] = 10, ["y"] = 5, ["param1"] = 15, ["z"] = 1, ["name"] = "default:stonebrick"}, {["x"] = 10, ["y"] = 5, ["z"] = 2, ["name"] = "default:stonebrick"}, {["x"] = 10, ["y"] = 5, ["z"] = 6, ["name"] = "default:stonebrick"}, {["x"] = 10, ["y"] = 5, ["z"] = 11, ["name"] = "default:stonebrick"}, {["x"] = 10, ["y"] = 5, ["z"] = 13, ["name"] = "default:stonebrick"}, {["x"] = 10, ["y"] = 5, ["z"] = 15, ["name"] = "default:stonebrick"}, {["x"] = 10, ["y"] = 5, ["z"] = 17, ["name"] = "default:stonebrick"}, {["x"] = 10, ["y"] = 5, ["z"] = 19, ["name"] = "default:stonebrick"}, {["x"] = 10, ["y"] = 5, ["z"] = 23, ["name"] = "default:stonebrick"}, {["x"] = 10, ["y"] = 5, ["z"] = 25, ["name"] = "default:stonebrick"}, {["x"] = 10, ["y"] = 5, ["z"] = 26, ["name"] = "default:stonebrick"}, {["x"] = 10, ["y"] = 5, ["z"] = 27, ["name"] = "default:stonebrick"}, {["x"] = 10, ["y"] = 5, ["z"] = 31, ["name"] = "default:stonebrick"}, {["x"] = 10, ["y"] = 5, ["z"] = 32, ["name"] = "default:stonebrick"}, {["x"] = 10, ["y"] = 5, ["param1"] = 15, ["z"] = 35, ["name"] = "default:stonebrick"}, {["x"] = 10, ["y"] = 6, ["param1"] = 15, ["z"] = 1, ["name"] = "default:stonebrick"}, {["x"] = 10, ["y"] = 6, ["z"] = 2, ["name"] = "default:stonebrick"}, {["x"] = 10, ["y"] = 6, ["z"] = 6, ["name"] = "default:stonebrick"}, {["x"] = 10, ["y"] = 6, ["z"] = 11, ["name"] = "default:stonebrick"}, {["x"] = 10, ["y"] = 6, ["z"] = 13, ["name"] = "default:stonebrick"}, {["x"] = 10, ["y"] = 6, ["z"] = 15, ["name"] = "default:stonebrick"}, {["x"] = 10, ["y"] = 6, ["z"] = 17, ["name"] = "default:stonebrick"}, {["x"] = 10, ["y"] = 6, ["z"] = 19, ["name"] = "default:stonebrick"}, {["x"] = 10, ["y"] = 6, ["z"] = 23, ["name"] = "default:stonebrick"}, {["x"] = 10, ["y"] = 6, ["z"] = 25, ["name"] = "default:stonebrick"}, {["x"] = 10, ["y"] = 6, ["z"] = 26, ["name"] = "default:stonebrick"}, {["x"] = 10, ["y"] = 6, ["z"] = 27, ["name"] = "default:stonebrick"}, {["x"] = 10, ["y"] = 6, ["z"] = 31, ["name"] = "default:stonebrick"}, {["x"] = 10, ["y"] = 6, ["z"] = 32, ["name"] = "default:stonebrick"}, {["x"] = 10, ["y"] = 6, ["param1"] = 15, ["z"] = 35, ["name"] = "default:stonebrick"}, {["x"] = 10, ["y"] = 7, ["param1"] = 15, ["z"] = 1, ["name"] = "default:stonebrick"}, {["x"] = 10, ["y"] = 7, ["z"] = 2, ["name"] = "default:stonebrick"}, {["x"] = 10, ["y"] = 7, ["z"] = 6, ["name"] = "default:stonebrick"}, {["x"] = 10, ["y"] = 7, ["z"] = 11, ["name"] = "default:stonebrick"}, {["x"] = 10, ["y"] = 7, ["z"] = 13, ["name"] = "default:stonebrick"}, {["x"] = 10, ["y"] = 7, ["z"] = 15, ["name"] = "default:stonebrick"}, {["x"] = 10, ["y"] = 7, ["z"] = 17, ["name"] = "default:stonebrick"}, {["x"] = 10, ["y"] = 7, ["z"] = 19, ["name"] = "default:stonebrick"}, {["x"] = 10, ["y"] = 7, ["z"] = 23, ["name"] = "default:stonebrick"}, {["x"] = 10, ["y"] = 7, ["z"] = 25, ["name"] = "default:stonebrick"}, {["x"] = 10, ["y"] = 7, ["z"] = 26, ["name"] = "default:stonebrick"}, {["x"] = 10, ["y"] = 7, ["z"] = 27, ["name"] = "default:stonebrick"}, {["x"] = 10, ["y"] = 7, ["z"] = 31, ["name"] = "default:stonebrick"}, {["x"] = 10, ["y"] = 7, ["z"] = 32, ["name"] = "default:stonebrick"}, {["x"] = 10, ["y"] = 7, ["param1"] = 15, ["z"] = 35, ["name"] = "default:stonebrick"}, {["x"] = 11, ["y"] = 2, ["z"] = 1, ["name"] = "default:dirt"}, {["x"] = 11, ["y"] = 2, ["param1"] = 15, ["z"] = 2, ["name"] = "default:dirt"}, {["x"] = 11, ["y"] = 2, ["param1"] = 15, ["z"] = 3, ["name"] = "default:dirt"}, {["x"] = 11, ["y"] = 2, ["param1"] = 15, ["z"] = 4, ["name"] = "default:dirt"}, {["x"] = 11, ["y"] = 2, ["param1"] = 15, ["z"] = 5, ["name"] = "default:dirt"}, {["x"] = 11, ["y"] = 2, ["param1"] = 15, ["z"] = 6, ["name"] = "default:dirt"}, {["x"] = 11, ["y"] = 2, ["param1"] = 15, ["z"] = 7, ["name"] = "default:dirt"}, {["x"] = 11, ["y"] = 2, ["param1"] = 15, ["z"] = 8, ["name"] = "default:dirt"}, {["x"] = 11, ["y"] = 2, ["param1"] = 15, ["z"] = 9, ["name"] = "default:dirt"}, {["x"] = 11, ["y"] = 2, ["param1"] = 15, ["z"] = 10, ["name"] = "default:dirt"}, {["x"] = 11, ["y"] = 2, ["param1"] = 15, ["z"] = 11, ["name"] = "default:dirt"}, {["x"] = 11, ["y"] = 2, ["param1"] = 15, ["z"] = 12, ["name"] = "default:dirt"}, {["x"] = 11, ["y"] = 2, ["param1"] = 15, ["z"] = 13, ["name"] = "default:dirt"}, {["x"] = 11, ["y"] = 2, ["param1"] = 15, ["z"] = 14, ["name"] = "default:dirt"}, {["x"] = 11, ["y"] = 2, ["param1"] = 15, ["z"] = 15, ["name"] = "default:dirt"}, {["x"] = 11, ["y"] = 2, ["param1"] = 15, ["z"] = 16, ["name"] = "default:dirt"}, {["x"] = 11, ["y"] = 2, ["param1"] = 15, ["z"] = 17, ["name"] = "default:dirt"}, {["x"] = 11, ["y"] = 2, ["param1"] = 15, ["z"] = 18, ["name"] = "default:dirt"}, {["x"] = 11, ["y"] = 2, ["param1"] = 15, ["z"] = 19, ["name"] = "default:dirt"}, {["x"] = 11, ["y"] = 2, ["param1"] = 15, ["z"] = 20, ["name"] = "default:dirt"}, {["x"] = 11, ["y"] = 2, ["param1"] = 15, ["z"] = 21, ["name"] = "default:dirt"}, {["x"] = 11, ["y"] = 2, ["param1"] = 15, ["z"] = 22, ["name"] = "default:dirt"}, {["x"] = 11, ["y"] = 2, ["param1"] = 15, ["z"] = 23, ["name"] = "default:dirt"}, {["x"] = 11, ["y"] = 2, ["param1"] = 15, ["z"] = 24, ["name"] = "default:dirt"}, {["x"] = 11, ["y"] = 2, ["param1"] = 15, ["z"] = 25, ["name"] = "default:dirt"}, {["x"] = 11, ["y"] = 2, ["param1"] = 15, ["z"] = 26, ["name"] = "default:dirt"}, {["x"] = 11, ["y"] = 2, ["param1"] = 15, ["z"] = 27, ["name"] = "default:dirt"}, {["x"] = 11, ["y"] = 2, ["param1"] = 15, ["z"] = 28, ["name"] = "default:dirt"}, {["x"] = 11, ["y"] = 2, ["param1"] = 15, ["z"] = 29, ["name"] = "default:dirt"}, {["x"] = 11, ["y"] = 2, ["param1"] = 15, ["z"] = 30, ["name"] = "default:dirt"}, {["x"] = 11, ["y"] = 2, ["param1"] = 15, ["z"] = 31, ["name"] = "default:dirt"}, {["x"] = 11, ["y"] = 2, ["param1"] = 15, ["z"] = 32, ["name"] = "default:dirt"}, {["x"] = 11, ["y"] = 2, ["param1"] = 15, ["z"] = 33, ["name"] = "default:dirt"}, {["x"] = 11, ["y"] = 2, ["param1"] = 15, ["z"] = 34, ["name"] = "default:dirt"}, {["x"] = 11, ["y"] = 2, ["z"] = 35, ["name"] = "default:dirt"}, {["x"] = 11, ["y"] = 3, ["param1"] = 15, ["z"] = 1, ["name"] = "default:stonebrick"}, {["x"] = 11, ["y"] = 3, ["z"] = 4, ["name"] = "default:stonebrick"}, {["x"] = 11, ["y"] = 3, ["z"] = 6, ["name"] = "default:stonebrick"}, {["x"] = 11, ["y"] = 3, ["z"] = 8, ["name"] = "default:stonebrick"}, {["x"] = 11, ["y"] = 3, ["z"] = 10, ["name"] = "default:stonebrick"}, {["x"] = 11, ["y"] = 3, ["z"] = 11, ["name"] = "default:stonebrick"}, {["x"] = 11, ["y"] = 3, ["z"] = 13, ["name"] = "default:stonebrick"}, {["x"] = 11, ["y"] = 3, ["z"] = 17, ["name"] = "default:stonebrick"}, {["x"] = 11, ["y"] = 3, ["z"] = 19, ["name"] = "default:stonebrick"}, {["x"] = 11, ["y"] = 3, ["z"] = 20, ["name"] = "default:stonebrick"}, {["x"] = 11, ["y"] = 3, ["z"] = 22, ["name"] = "default:stonebrick"}, {["x"] = 11, ["y"] = 3, ["z"] = 23, ["name"] = "default:stonebrick"}, {["x"] = 11, ["y"] = 3, ["z"] = 24, ["name"] = "default:stonebrick"}, {["x"] = 11, ["y"] = 3, ["z"] = 28, ["name"] = "default:stonebrick"}, {["x"] = 11, ["y"] = 3, ["z"] = 29, ["name"] = "default:stonebrick"}, {["x"] = 11, ["y"] = 3, ["z"] = 33, ["name"] = "default:stonebrick"}, {["x"] = 11, ["y"] = 3, ["param1"] = 15, ["z"] = 35, ["name"] = "default:stonebrick"}, {["x"] = 11, ["y"] = 4, ["param1"] = 15, ["z"] = 1, ["name"] = "default:stonebrick"}, {["x"] = 11, ["y"] = 4, ["z"] = 4, ["name"] = "default:stonebrick"}, {["x"] = 11, ["y"] = 4, ["z"] = 6, ["name"] = "default:stonebrick"}, {["x"] = 11, ["y"] = 4, ["z"] = 8, ["name"] = "default:stonebrick"}, {["x"] = 11, ["y"] = 4, ["z"] = 10, ["name"] = "default:stonebrick"}, {["x"] = 11, ["y"] = 4, ["z"] = 11, ["name"] = "default:stonebrick"}, {["x"] = 11, ["y"] = 4, ["z"] = 13, ["name"] = "default:stonebrick"}, {["x"] = 11, ["y"] = 4, ["z"] = 17, ["name"] = "default:stonebrick"}, {["x"] = 11, ["y"] = 4, ["z"] = 19, ["name"] = "default:stonebrick"}, {["x"] = 11, ["y"] = 4, ["z"] = 20, ["name"] = "default:stonebrick"}, {["x"] = 11, ["y"] = 4, ["z"] = 22, ["name"] = "default:stonebrick"}, {["x"] = 11, ["y"] = 4, ["z"] = 23, ["name"] = "default:stonebrick"}, {["x"] = 11, ["y"] = 4, ["z"] = 24, ["name"] = "default:stonebrick"}, {["x"] = 11, ["y"] = 4, ["z"] = 28, ["name"] = "default:stonebrick"}, {["x"] = 11, ["y"] = 4, ["z"] = 29, ["name"] = "default:stonebrick"}, {["x"] = 11, ["y"] = 4, ["z"] = 33, ["name"] = "default:stonebrick"}, {["x"] = 11, ["y"] = 4, ["param1"] = 15, ["z"] = 35, ["name"] = "default:stonebrick"}, {["x"] = 11, ["y"] = 5, ["param1"] = 15, ["z"] = 1, ["name"] = "default:stonebrick"}, {["x"] = 11, ["y"] = 5, ["z"] = 4, ["name"] = "default:stonebrick"}, {["x"] = 11, ["y"] = 5, ["z"] = 6, ["name"] = "default:stonebrick"}, {["x"] = 11, ["y"] = 5, ["z"] = 8, ["name"] = "default:stonebrick"}, {["x"] = 11, ["y"] = 5, ["z"] = 10, ["name"] = "default:stonebrick"}, {["x"] = 11, ["y"] = 5, ["z"] = 11, ["name"] = "default:stonebrick"}, {["x"] = 11, ["y"] = 5, ["z"] = 13, ["name"] = "default:stonebrick"}, {["x"] = 11, ["y"] = 5, ["z"] = 17, ["name"] = "default:stonebrick"}, {["x"] = 11, ["y"] = 5, ["z"] = 19, ["name"] = "default:stonebrick"}, {["x"] = 11, ["y"] = 5, ["z"] = 20, ["name"] = "default:stonebrick"}, {["x"] = 11, ["y"] = 5, ["z"] = 22, ["name"] = "default:stonebrick"}, {["x"] = 11, ["y"] = 5, ["z"] = 23, ["name"] = "default:stonebrick"}, {["x"] = 11, ["y"] = 5, ["z"] = 24, ["name"] = "default:stonebrick"}, {["x"] = 11, ["y"] = 5, ["z"] = 28, ["name"] = "default:stonebrick"}, {["x"] = 11, ["y"] = 5, ["z"] = 29, ["name"] = "default:stonebrick"}, {["x"] = 11, ["y"] = 5, ["z"] = 33, ["name"] = "default:stonebrick"}, {["x"] = 11, ["y"] = 5, ["param1"] = 15, ["z"] = 35, ["name"] = "default:stonebrick"}, {["x"] = 11, ["y"] = 6, ["param1"] = 15, ["z"] = 1, ["name"] = "default:stonebrick"}, {["x"] = 11, ["y"] = 6, ["z"] = 4, ["name"] = "default:stonebrick"}, {["x"] = 11, ["y"] = 6, ["z"] = 6, ["name"] = "default:stonebrick"}, {["x"] = 11, ["y"] = 6, ["z"] = 8, ["name"] = "default:stonebrick"}, {["x"] = 11, ["y"] = 6, ["z"] = 10, ["name"] = "default:stonebrick"}, {["x"] = 11, ["y"] = 6, ["z"] = 11, ["name"] = "default:stonebrick"}, {["x"] = 11, ["y"] = 6, ["z"] = 13, ["name"] = "default:stonebrick"}, {["x"] = 11, ["y"] = 6, ["z"] = 17, ["name"] = "default:stonebrick"}, {["x"] = 11, ["y"] = 6, ["z"] = 19, ["name"] = "default:stonebrick"}, {["x"] = 11, ["y"] = 6, ["z"] = 20, ["name"] = "default:stonebrick"}, {["x"] = 11, ["y"] = 6, ["z"] = 22, ["name"] = "default:stonebrick"}, {["x"] = 11, ["y"] = 6, ["z"] = 23, ["name"] = "default:stonebrick"}, {["x"] = 11, ["y"] = 6, ["z"] = 24, ["name"] = "default:stonebrick"}, {["x"] = 11, ["y"] = 6, ["z"] = 28, ["name"] = "default:stonebrick"}, {["x"] = 11, ["y"] = 6, ["z"] = 29, ["name"] = "default:stonebrick"}, {["x"] = 11, ["y"] = 6, ["z"] = 33, ["name"] = "default:stonebrick"}, {["x"] = 11, ["y"] = 6, ["param1"] = 15, ["z"] = 35, ["name"] = "default:stonebrick"}, {["x"] = 11, ["y"] = 7, ["param1"] = 15, ["z"] = 1, ["name"] = "default:stonebrick"}, {["x"] = 11, ["y"] = 7, ["z"] = 4, ["name"] = "default:stonebrick"}, {["x"] = 11, ["y"] = 7, ["z"] = 6, ["name"] = "default:stonebrick"}, {["x"] = 11, ["y"] = 7, ["z"] = 8, ["name"] = "default:stonebrick"}, {["x"] = 11, ["y"] = 7, ["z"] = 10, ["name"] = "default:stonebrick"}, {["x"] = 11, ["y"] = 7, ["z"] = 11, ["name"] = "default:stonebrick"}, {["x"] = 11, ["y"] = 7, ["z"] = 13, ["name"] = "default:stonebrick"}, {["x"] = 11, ["y"] = 7, ["z"] = 17, ["name"] = "default:stonebrick"}, {["x"] = 11, ["y"] = 7, ["z"] = 19, ["name"] = "default:stonebrick"}, {["x"] = 11, ["y"] = 7, ["z"] = 20, ["name"] = "default:stonebrick"}, {["x"] = 11, ["y"] = 7, ["z"] = 22, ["name"] = "default:stonebrick"}, {["x"] = 11, ["y"] = 7, ["z"] = 23, ["name"] = "default:stonebrick"}, {["x"] = 11, ["y"] = 7, ["z"] = 24, ["name"] = "default:stonebrick"}, {["x"] = 11, ["y"] = 7, ["z"] = 28, ["name"] = "default:stonebrick"}, {["x"] = 11, ["y"] = 7, ["z"] = 29, ["name"] = "default:stonebrick"}, {["x"] = 11, ["y"] = 7, ["z"] = 33, ["name"] = "default:stonebrick"}, {["x"] = 11, ["y"] = 7, ["param1"] = 15, ["z"] = 35, ["name"] = "default:stonebrick"}, {["x"] = 12, ["y"] = 2, ["z"] = 1, ["name"] = "default:dirt"}, {["x"] = 12, ["y"] = 2, ["param1"] = 15, ["z"] = 2, ["name"] = "default:dirt"}, {["x"] = 12, ["y"] = 2, ["param1"] = 15, ["z"] = 3, ["name"] = "default:dirt"}, {["x"] = 12, ["y"] = 2, ["param1"] = 15, ["z"] = 4, ["name"] = "default:dirt"}, {["x"] = 12, ["y"] = 2, ["param1"] = 15, ["z"] = 5, ["name"] = "default:dirt"}, {["x"] = 12, ["y"] = 2, ["param1"] = 15, ["z"] = 6, ["name"] = "default:dirt"}, {["x"] = 12, ["y"] = 2, ["param1"] = 15, ["z"] = 7, ["name"] = "default:dirt"}, {["x"] = 12, ["y"] = 2, ["param1"] = 15, ["z"] = 8, ["name"] = "default:dirt"}, {["x"] = 12, ["y"] = 2, ["param1"] = 15, ["z"] = 9, ["name"] = "default:dirt"}, {["x"] = 12, ["y"] = 2, ["param1"] = 15, ["z"] = 10, ["name"] = "default:dirt"}, {["x"] = 12, ["y"] = 2, ["param1"] = 15, ["z"] = 11, ["name"] = "default:dirt"}, {["x"] = 12, ["y"] = 2, ["param1"] = 15, ["z"] = 12, ["name"] = "default:dirt"}, {["x"] = 12, ["y"] = 2, ["param1"] = 15, ["z"] = 13, ["name"] = "default:dirt"}, {["x"] = 12, ["y"] = 2, ["param1"] = 15, ["z"] = 14, ["name"] = "default:dirt"}, {["x"] = 12, ["y"] = 2, ["param1"] = 15, ["z"] = 15, ["name"] = "default:dirt"}, {["x"] = 12, ["y"] = 2, ["param1"] = 15, ["z"] = 16, ["name"] = "default:dirt"}, {["x"] = 12, ["y"] = 2, ["param1"] = 15, ["z"] = 17, ["name"] = "default:dirt"}, {["x"] = 12, ["y"] = 2, ["param1"] = 15, ["z"] = 18, ["name"] = "default:dirt"}, {["x"] = 12, ["y"] = 2, ["param1"] = 15, ["z"] = 19, ["name"] = "default:dirt"}, {["x"] = 12, ["y"] = 2, ["param1"] = 15, ["z"] = 20, ["name"] = "default:dirt"}, {["x"] = 12, ["y"] = 2, ["param1"] = 15, ["z"] = 21, ["name"] = "default:dirt"}, {["x"] = 12, ["y"] = 2, ["param1"] = 15, ["z"] = 22, ["name"] = "default:dirt"}, {["x"] = 12, ["y"] = 2, ["param1"] = 15, ["z"] = 23, ["name"] = "default:dirt"}, {["x"] = 12, ["y"] = 2, ["param1"] = 15, ["z"] = 24, ["name"] = "default:dirt"}, {["x"] = 12, ["y"] = 2, ["param1"] = 15, ["z"] = 25, ["name"] = "default:dirt"}, {["x"] = 12, ["y"] = 2, ["param1"] = 15, ["z"] = 26, ["name"] = "default:dirt"}, {["x"] = 12, ["y"] = 2, ["param1"] = 15, ["z"] = 27, ["name"] = "default:dirt"}, {["x"] = 12, ["y"] = 2, ["param1"] = 15, ["z"] = 28, ["name"] = "default:dirt"},